Workbook

Sheet DS nhan HPTN
A1: DANH SÁCH SINH VIÊN THỰC HIỆN HỌC PHẦN TỐT NGHIỆP - HỌC KỲ 2 NĂM HỌC 2025-2026
A2: (Kèm theo Quyết định số /QĐ-ĐHTL-PH ngày tháng năm 2026)
A4: STT | B4: MSSV | C4: Họ và Tên | D4: Lớp | E4: Số điểm tích lũy | F4: Tên Đề Tài | I4: GV Hướng Dẫn 1 | J4: GV Hướng Dẫn 2 | K4: Ngành | L4: Bộ Môn
A5: 1 | B5: 1951065174 | C5: Hà Lê Duy | D5: S22-61TH1 | E5: 2.46 | F5: Xây dựng hệ thống quản lý bán hàng đa nền tảng dựa trên Flutter và Firebase | H5: =IF(G5=0,F5,G5) -> Xây dựng hệ thống quản lý bán hàng đa nền tảng dựa trên Flutter và Firebase | I5: TS. Hoàng Thị Kiều Anh | K5: Công nghệ thông tin | L5: Công nghệ thông tin | M5: =VLOOKUP(B5,Sheet4!D:O,11,0) -> https://drive.google.com/open?id=1NukpykEHyFBscM6XTv794v7AM3Y8TmCt
A6: 2 | B6: 2051067522 | C6: Nguyễn Ngọc Bảo | D6: S23-62TH | E6: 2.78 | F6: Xây dựng website định giá Bất động sản tại Thành phố Hồ Chí Minh thông qua kỹ thuật học máy | H6: =IF(G6=0,F6,G6) -> Xây dựng website định giá Bất động sản tại Thành phố Hồ Chí Minh thông qua kỹ thuật học máy | I6: ThS. Trần Ngọc Dân | K6: Công nghệ thông tin | L6: Công nghệ thông tin | M6: =VLOOKUP(B6,Sheet4!D:O,11,0) -> https://drive.google.com/open?id=1RxKckfufymMb2S5w6arS_vAwn-PGITZ-
A7: 3 | B7: 2151067055 | C7: Chung Gia Bảo | D7: S24-63CNTT1 | E7: 2.15 | F7: Xây dựng hệ thống website Gia Bao kinh doanh thiết bị di động trực tuyến tích hợp quản lý kho và đơn hàng | H7: =IF(G7=0,F7,G7) -> Xây dựng hệ thống website Gia Bao kinh doanh thiết bị di động trực tuyến tích hợp quản lý kho và đơn hàng | I7: TS. Hoàng Thị Kiều Anh | K7: Công nghệ thông tin | L7: Công nghệ thông tin | M7: =VLOOKUP(B7,Sheet4!D:O,11,0) -> https://drive.google.com/open?id=1hMC0Mvs7iLgTIM_aYVuUNderRfNFF9ER
A8: 4 | B8: 2151067060 | C8: Võ Hoàn Lạc | D8: S24-63CNTT1 | E8: 2.21 | F8: Xây dựng website thời trang LaHo tích hợp chatbot hỗ trợ và tư vấn khách hàng | H8: =IF(G8=0,F8,G8) -> Xây dựng website thời trang LaHo tích hợp chatbot hỗ trợ và tư vấn khách hàng | I8: TS. Hoàng Thị Kiều Anh | K8: Công nghệ thông tin | L8: Công nghệ thông tin | M8: =VLOOKUP(B8,Sheet4!D:O,11,0) -> https://drive.google.com/open?id=1jDc3GRI1k-EoZYHVhvVaZz3e8nRmIitx
A9: 5 | B9: 2151067238 | C9: Võ Lê Hậu | D9: S24-63CNTT1 | E9: 2.18 | F9: Xây dựng ứng dụng quản lý học tại trung tâm giáo dục Thành Công | H9: =IF(G9=0,F9,G9) -> Xây dựng ứng dụng quản lý học tại trung tâm giáo dục Thành Công | I9: ThS. Tống Thị Nhung | K9: Công nghệ thông tin | L9: Công nghệ thông tin | M9: =VLOOKUP(B9,Sheet4!D:O,11,0) -> https://drive.google.com/open?id=1Fv3gvQMTM0OJvwadGlvs4qKBwSjibCrZ
A10: 6 | B10: 2151067630 | C10: Lê Văn Bảo | D10: S24-63CNTT2 | E10: 2.07 | F10: Thiết kế xây dựng sensor đo và theo dõi độ mặn trong quản lý chất lượng nước | H10: =IF(G10=0,F10,G10) -> Thiết kế xây dựng sensor đo và theo dõi độ mặn trong quản lý chất lượng nước | I10: TS. Hoàng Văn Quý | K10: Công nghệ thông tin | L10: Công nghệ thông tin | M10: =VLOOKUP(B10,Sheet4!D:O,11,0) -> https://drive.google.com/open?id=1oTCNKQunSM2GxaM9ow73QHcn2NEdcmjt
A11: 7 | B11: 2151067620 | C11: Nguyễn Nam Nhân | D11: S24-63CNTT2 | E11: 2.5 | F11: Xây dựng website quản lý kho hàng ứng dụng công nghệ AI | H11: =IF(G11=0,F11,G11) -> Xây dựng website quản lý kho hàng ứng dụng công nghệ AI | I11: ThS. Trần Ngọc Dân | K11: Công nghệ thông tin | L11: Công nghệ thông tin | M11: =VLOOKUP(B11,Sheet4!D:O,11,0) -> https://drive.google.com/open?id=1USTn0hnyhpWUAjz86eQ3qAtFnwMBTgdP
A12: 8 | B12: 2151067610 | C12: Võ Trần Luân | D12: S24-63CNTT2 | E12: 2.42 | F12: Thiết kế và xây dựng hệ thống điều khiển nhà thông minh trên nền tảng ESP32S | H12: =IF(G12=0,F12,G12) -> Thiết kế và xây dựng hệ thống điều khiển nhà thông minh trên nền tảng ESP32S | I12: ThS. Nguyễn Thị Hồng Tú | K12: Công nghệ thông tin | L12: Công nghệ thông tin | M12: =VLOOKUP(B12,Sheet4!D:O,11,0) -> https://drive.google.com/open?id=1VVm3CwhbW6263zGXBZlA4La7PDVPiOMl
A13: 9 | B13: 2151067072 | C13: Tăng Phước Sang | D13: S24-63CNTT2 | E13: 2.05 | F13: Thiết kế và phát triển website du lịch trực tuyến VietExplore | H13: =IF(G13=0,F13,G13) -> Thiết kế và phát triển website du lịch trực tuyến VietExplore | I13: ThS. Vũ Thị Hạnh | K13: Công nghệ thông tin | L13: Công nghệ thông tin | M13: =VLOOKUP(B13,Sheet4!D:O,11,0) -> https://drive.google.com/open?id=1gi4vAwZjUEa0-f2MksxmiHLcGaevDjZB
A14: 10 | B14: 2151067053 | C14: Hồ Minh Anh | D14: S24-63CNTT2 | E14: 2.42 | F14: Phát triển ứng dụng di động quản lý sự kiện sử dụng Flutter | H14: =IF(G14=0,F14,G14) -> Phát triển ứng dụng di động quản lý sự kiện sử dụng Flutter | I14: ThS. Nguyễn Thị Hồng Tú | K14: Công nghệ thông tin | L14: Công nghệ thông tin | M14: =VLOOKUP(B14,Sheet4!D:O,11,0) -> https://drive.google.com/open?id=1abTZwxvI4026_-6zf0KFF980uSoPKWGq
A15: 11 | B15: 2151067239 | C15: Đặng Nguyễn Minh Hoàng | D15: S24-63CNTT2 | E15: 2.42 | F15: Xây dựng website quản lý dự án cho Công ty Vision | H15: =IF(G15=0,F15,G15) -> Xây dựng website quản lý dự án cho Công ty Vision | I15: ThS. Nguyễn Thị Hồng Tú | K15: Công nghệ thông tin | L15: Công nghệ thông tin | M15: =VLOOKUP(B15,Sheet4!D:O,11,0) -> https://drive.google.com/open?id=1qlMKQR0sHCZ06bhq3nV_Dji1znjvchv0
A16: 12 | B16: 2251068218 | C16: Lê Võ Nhựt Nguyên | D16: S25-64CNTT | E16: 2.91 | F16: Thiết kế và xây dựng hệ thống IoT giám sát, chống trộm và cảnh báo tai nạn cho xe máy | H16: =IF(G16=0,F16,G16) -> Thiết kế và xây dựng hệ thống IoT giám sát, chống trộm và cảnh báo tai nạn cho xe máy | I16: ThS. Vũ Thị Hạnh | K16: Công nghệ thông tin | L16: Công nghệ thông tin | M16: =VLOOKUP(B16,Sheet4!D:O,11,0) -> https://drive.google.com/open?id=1jSoOOKoQQKFeTo7CsFbI2CooyxnI8GLI
... A62: 58 | B62: 2154027107 | C62: Hồ Phạm Khánh Linh | D62: S24-63QT-MAR | E62: 1.91 | F62: Nâng cao hiệu quả tuyển dụng nhân sự tại Công ty TNHH EX ADMEDIA ASIA | H62: =IF(G62=0,F62,G62) -> Nâng cao hiệu quả tuyển dụng nhân sự tại Công ty TNHH EX ADMEDIA ASIA | I62: ThS. Tăng Thị Lưu | K62: Quản trị Marketing | L62: Kế toán & Quản trị kinh doanh | M62: =VLOOKUP(B62,Sheet4!D:O,11,0) -> https://drive.google.com/open?id=13ul2Zoi1KuSVnYE8laXl50MgYTT0hYt4
A63: 59 | B63: 2154027093 | C63: Võ Thị Hồng Hạnh | D63: S24-63QT-MAR | E63: 1.86 | F63: Giải pháp thúc đẩy hiệu quả hoạt động bán hàng cá nhân của đội ngũ môi giới tại Công ty CP Đầu Tư Và Dịch Vụ Đất Xanh Miền Nam | G63: Giải pháp thúc đẩy hiệu quả hoạt động bán hàng cá nhân của đội ngũ môi giới tại Công Ty TNHH Tập Đoàn Nam Việt Group | H63: =IF(G63=0,F63,G63) -> Giải pháp thúc đẩy hiệu quả hoạt động bán hàng cá nhân của đội ngũ môi giới tại Công Ty TNHH Tập Đoàn Nam Việt Group | I63: ThS. Tăng Thị Lưu | K63: Quản trị Marketing | L63: Kế toán & Quản trị kinh doanh | M63: =VLOOKUP(B63,Sheet4!D:O,11,0) -> https://drive.google.com/open?id=1UcYBdXxdGVb4qcRw2wUrSUOGJRrLGMk7
A64: 60 | B64: 2154027657 | C64: Đỗ Ngọc Yến Trân | D64: S24-63QT-MAR | E64: 2.2 | F64: Giải pháp nâng cao hiệu quả hoạt động digital marketing tại Công ty Cổ phần Công nghệ Y tế Minh Anh | H64: =IF(G64=0,F64,G64) -> Giải pháp nâng cao hiệu quả hoạt động digital marketing tại Công ty Cổ phần Công nghệ Y tế Minh Anh | I64: ThS. Tăng Thị Lưu | K64: Quản trị Marketing | L64: Kế toán & Quản trị kinh doanh | M64: =VLOOKUP(B64,Sheet4!D:O,11,0) -> https://drive.google.com/open?id=186pPY33DDb64kZ-XQqFsXsEkg_6J7gNO
A65: 61 | B65: 2154027138 | C65: Trần Mạnh Trung | D65: S24-63QT-MAR | E65: 2.01 | F65: Nâng cao hiệu quả hoạt động truyền thông marketing trên nền tảng Tiktok tại Công ty TNHH Meishang Viet Nam | H65: =IF(G65=0,F65,G65) -> Nâng cao hiệu quả hoạt động truyền thông marketing trên nền tảng Tiktok tại Công ty TNHH Meishang Viet Nam | I65: ThS. Tăng Thị Lưu | K65: Quản trị Marketing | L65: Kế toán & Quản trị kinh doanh | M65: =VLOOKUP(B65,Sheet4!D:O,11,0) -> https://drive.google.com/open?id=1XwWyaI01Q6RIxtkRJNpXQFv_CIQh7ngd
A66: 62 | B66: 2254028424 | C66: Huỳnh Thị Ngọc Hiên | D66: S25-64QT-MAR | E66: 2.13 | F66: Nâng cao hiệu quả hoạt động chăm sóc khách hàng tại Công ty TNHH MTV chuyển phát nhanh Thuận Phong | H66: =IF(G66=0,F66,G66) -> Nâng cao hiệu quả hoạt động chăm sóc khách hàng tại Công ty TNHH MTV chuyển phát nhanh Thuận Phong | I66: ThS. Tăng Thị Lưu | K66: Quản trị Marketing | L66: Kế toán & Quản trị kinh doanh | M66: =VLOOKUP(B66,Sheet4!D:O,11,0) -> https://drive.google.com/open?id=1h_yMqLE2oWAb8cYOoaP8XN3wAOMJjVos
A67: 63 | B67: 2254028423 | C67: Cao Thị Thanh Hảo | D67: S25-64QT-MAR | E67: 2.26 | F67: Nâng cao hiệu quả hoạt động cho vay đối với khách hàng cá nhân tại Ngân hàng Thương mại Cổ phần Quân đội - Chi nhánh Tân Cảng | H67: =IF(G67=0,F67,G67) -> Nâng cao hiệu quả hoạt động cho vay đối với khách hàng cá nhân tại Ngân hàng Thương mại Cổ phần Quân đội - Chi nhánh Tân Cảng | I67: ThS. Tăng Thị Lưu | K67: Quản trị Marketing | L67: Kế toán & Quản trị kinh doanh | M67: =VLOOKUP(B67,Sheet4!D:O,11,0) -> https://drive.google.com/open?id=15pwtBHj0ToRISUmtw3ZNG7AeZeAmGBNt
A68: 64 | B68: 2254028437 | C68: Nguyễn Huỳnh Ngọc Lam | D68: S25-64QT-MAR | E68: 2.6 | F68: Nâng cao hiệu quả hoạt động truyền thông marketing trên nền tảng Tiktok tại Công ty TNHH Esuhai | H68: =IF(G68=0,F68,G68) -> Nâng cao hiệu quả hoạt động truyền thông marketing trên nền tảng Tiktok tại Công ty TNHH Esuhai | I68: ThS. Tăng Thị Lưu | K68: Quản trị Marketing | L68: Kế toán & Quản trị kinh doanh | M68: =VLOOKUP(B68,Sheet4!D:O,11,0) -> https://drive.google.com/open?id=1-mWgSHPSVqD86z2P0N2ygTTKTHb6lHQM
A69: 65 | B69: 2254028466 | C69: Võ Thị Thúy Quy | D69: S25-64QT-MAR | E69: 3.11 | F69: Nâng cao hiệu quả hoạt động truyền thông marketing trên nền tảng TikTok tại Công ty TNHH MTV Vật Liệu Cách Nhiệt Việt Nhật | H69: =IF(G69=0,F69,G69) -> Nâng cao hiệu quả hoạt động truyền thông marketing trên nền tảng TikTok tại Công ty TNHH MTV Vật Liệu Cách Nhiệt Việt Nhật | I69: ThS. Tăng Thị Lưu | K69: Quản trị Marketing | L69: Kế toán & Quản trị kinh doanh | M69: =VLOOKUP(B69,Sheet4!D:O,11,0) -> https://drive.google.com/open?id=1sbebNb_twPY7qL5H6riAX1VvF0IJWEUN
A70: 66 | B70: 2254028455 | C70: Lê Thị Hồng Nhi | D70: S25-64QT-MAR | E70: 2.89 | F70: Nâng cao hiệu quả hoạt động truyền thông marketing trên nền tảng Facebook tại Công ty Cổ phần Đầu tư WorldLine | H70: =IF(G70=0,F70,G70) -> Nâng cao hiệu quả hoạt động truyền thông marketing trên nền tảng Facebook tại Công ty Cổ phần Đầu tư WorldLine | I70: ThS. Tăng Thị Lưu | K70: Quản trị Marketing | L70: Kế toán & Quản trị kinh doanh | M70: =VLOOKUP(B70,Sheet4!D:O,11,0) -> https://drive.google.com/open?id=1YwVUCIzSfa9kT2JJlRotqBfJyI4zn63T
A71: 67 | B71: 2254028412 | C71: Võ Ngọc Tú Chi | D71: S25-64QT-MAR | E71: 2.1 | F71: Nâng cao hiệu quả hoạt động truyền thông marketing trên nền tảng Facebook tại Công ty TNHH Thế Giới Nha Khoa AB | H71: =IF(G71=0,F71,G71) -> Nâng cao hiệu quả hoạt động truyền thông marketing trên nền tảng Facebook tại Công ty TNHH Thế Giới Nha Khoa AB | I71: ThS. Tăng Thị Lưu | K71: Quản trị Marketing | L71: Kế toán & Quản trị kinh doanh | M71: =VLOOKUP(B71,Sheet4!D:O,11,0) -> https://drive.google.com/open?id=1NgHLwjOeaeU17f-Dnt08lUb3vVGsml5D
A72: 68 | B72: 2254028454 | C72: Nguyễn Thành Nhân | D72: S25-64QT-MAR | E72: 2.2 | F72: Giải pháp nâng cao hiệu quả hoạt động chăm sóc khách hàng tại Công ty TNHH Thương Mại Và Kỹ Thuật Sanwa | H72: =IF(G72=0,F72,G72) -> Giải pháp nâng cao hiệu quả hoạt động chăm sóc khách hàng tại Công ty TNHH Thương Mại Và Kỹ Thuật Sanwa | I72: ThS. Tăng Thị Lưu | K72: Quản trị Marketing | L72: Kế toán & Quản trị kinh doanh | M72: =VLOOKUP(B72,Sheet4!D:O,11,0) -> https://drive.google.com/open?id=1OXgnrVbAsSKzxKswapf8G-V9fqD7aH9G
A73: 69 | B73: 2254028422 | C73: Nguyễn Lê Thu Hà | D73: S25-64QT-MAR | E73: 2.15 | F73: Giải pháp nâng cao hiệu quả hoạt động chăm sóc khách hàng tại Công ty TNHH Thiết bị Quảng cáo Nam Mỹ | H73: =IF(G73=0,F73,G73) -> Giải pháp nâng cao hiệu quả hoạt động chăm sóc khách hàng tại Công ty TNHH Thiết bị Quảng cáo Nam Mỹ | I73: ThS. Tăng Thị Lưu | K73: Quản trị Marketing | L73: Kế toán & Quản trị kinh doanh | M73: =VLOOKUP(B73,Sheet4!D:O,11,0) -> https://drive.google.com/open?id=1npVHdgeVs3bqgiVUlm1qViBdx-dH2XF5
A74: 70 | B74: 2254028479 | C74: Võ Thị Kim Thoa | D74: S25-64QT-MAR | E74: 2.29 | F74: Hoàn thiện công tác chăm sóc khách hàng cá nhân trong hoạt động tín dụng tại Ngân hàng Thương mại Cổ phần Quân đội - Chi nhánh Tân Cảng | H74: =IF(G74=0,F74,G74) -> Hoàn thiện công tác chăm sóc khách hàng cá nhân trong hoạt động tín dụng tại Ngân hàng Thương mại Cổ phần Quân đội - Chi nhánh Tân Cảng | I74: ThS. Tăng Thị Lưu | K74: Quản trị Marketing | L74: Kế toán & Quản trị kinh doanh | M74: =VLOOKUP(B74,Sheet4!D:O,11,0) -> https://drive.google.com/open?id=1B_inG1Cd9LATzZaxOCF4eBp6YdxE4HaU
A75: 71 | B75: 2254028421 | C75: Võ Thị Ngọc Giàu | D75: S25-64QT-MAR | E75: 2.26 | F75: Nâng cao hiệu quả hoạt động bán hàng tại Công ty TNHH Đầu tư Thương mại Linh Kiệt | H75: =IF(G75=0,F75,G75) -> Nâng cao hiệu quả hoạt động bán hàng tại Công ty TNHH Đầu tư Thương mại Linh Kiệt | I75: ThS. Tăng Thị Lưu | K75: Quản trị Marketing | L75: Kế toán & Quản trị kinh doanh | M75: =VLOOKUP(B75,Sheet4!D:O,11,0) -> https://drive.google.com/open?id=1OWI3yepbiHuE44r4tNiwKf30LrZE1aQE
... A93: 89 | B93: 2254028452 | C93: Nguyễn Thị Thúy Nga | D93: S25-64QT-KDQT | E93: 2.72 | F93: Hoàn thiện công tác tuyển dụng nhân sự tại Công ty Cổ phần Kỹ thuật Việt Sơn | H93: =IF(G93=0,F93,G93) -> Hoàn thiện công tác tuyển dụng nhân sự tại Công ty Cổ phần Kỹ thuật Việt Sơn | I93: TS. Trần Thị Thanh Huyền | K93: Quản trị kinh doanh quốc tế | L93: Kế toán & Quản trị kinh doanh | M93: =VLOOKUP(B93,Sheet4!D:O,11,0) -> https://drive.google.com/open?id=1CD07aSIE8VQuH43Br-0Qp4Kw3Q3d0jP_
A94: 90 | B94: 2254023910 | C94: NGÔ SỸ SIÊU | D94: S25-64QT-KDQT | E94: 2.69 | F94: Thực trạng và giải pháp nâng cao hiệu quả hoạt động tuyển sinh tại Trường Cao đẳng nghề Hoa Sen | G94: Giải pháp nâng cao hiệu quả hoạt động truyền thông marketing tại Trường Cao đẳng nghề Hoa Sen | H94: =IF(G94=0,F94,G94) -> Giải pháp nâng cao hiệu quả hoạt động truyền thông marketing tại Trường Cao đẳng nghề Hoa Sen | I94: ThS. Tăng Thị Lưu | K94: Quản trị kinh doanh quốc tế | L94: Kế toán & Quản trị kinh doanh | M94: =VLOOKUP(B94,Sheet4!D:O,11,0) -> https://drive.google.com/open?id=1P7c-TZO9yPDlrijQhIJanYF-HBNjLLGG
A95: 91 | B95: 2254028416 | C95: Nguyễn Thị Thùy Dung | D95: S25-64QT-KDQT | E95: 2.64 | F95: Hoàn thiện công tác tuyển dụng nhân sự tại Công ty TNHH Vật Liệu Cách Nhiệt Việt Nhật | H95: =IF(G95=0,F95,G95) -> Hoàn thiện công tác tuyển dụng nhân sự tại Công ty TNHH Vật Liệu Cách Nhiệt Việt Nhật | I95: TS. Trần Thị Thanh Huyền | K95: Quản trị kinh doanh quốc tế | L95: Kế toán & Quản trị kinh doanh | M95: =VLOOKUP(B95,Sheet4!D:O,11,0) -> https://drive.google.com/open?id=1OKHXJcz_aR0iAwQJ127Tq59tWaT9atga
A96: 92 | B96: 2154027131 | C96: Hoàng Thị Hoài Thương | D96: S24-63QT-KDQT | E96: 3.07 | F96: Hoàn thiện quy trình thông quan hàng thức ăn chăn nuôi nhập khẩu bằng đường biển tại Công ty TNHH Xuất Nhập Khẩu Minh Trang SG | H96: =IF(G96=0,F96,G96) -> Hoàn thiện quy trình thông quan hàng thức ăn chăn nuôi nhập khẩu bằng đường biển tại Công ty TNHH Xuất Nhập Khẩu Minh Trang SG | I96: ThS. Tăng Thị Lưu | K96: Quản trị kinh doanh quốc tế | L96: Kế toán & Quản trị kinh doanh | M96: =VLOOKUP(B96,Sheet4!D:O,11,0) -> https://drive.google.com/open?id=1h8F1hj02X2I8NqbtkzymCvxMgGUe2yZw
A97: 93 | B97: 2254028462 | C97: Đỗ Thị Thu Phương | D97: S25-64QT-KDQT | E97: 2.52 | F97: Giải pháp phát triển ngành hàng độc quyền tại Công ty TNHH Mê Đi Ca | H97: =IF(G97=0,F97,G97) -> Giải pháp phát triển ngành hàng độc quyền tại Công ty TNHH Mê Đi Ca | I97: TS. Hà Kiên Tân | K97: Quản trị kinh doanh quốc tế | L97: Kế toán & Quản trị kinh doanh | M97: =VLOOKUP(B97,Sheet4!D:O,11,0) -> https://drive.google.com/open?id=167CJNkXJIQBMaKfLDFo7gpuBu5jm3m3x
A98: 94 | B98: 2254028449 | C98: Nguyễn Ánh Minh | D98: S25-64QT-KDQT | E98: 2.82 | F98: Hoàn thiện hoạt động thanh toán quốc tế cho các doanh nghiệp vận tải tại Ngân hàng Vietcombank - Chi nhánh TP. Hồ Chí Minh | H98: =IF(G98=0,F98,G98) -> Hoàn thiện hoạt động thanh toán quốc tế cho các doanh nghiệp vận tải tại Ngân hàng Vietcombank - Chi nhánh TP. Hồ Chí Minh | I98: TS. Hà Kiên Tân | K98: Quản trị kinh doanh quốc tế | L98: Kế toán & Quản trị kinh doanh | M98: =VLOOKUP(B98,Sheet4!D:O,11,0) -> https://drive.google.com/open?id=1Ddm6cPr4fW_ywBVT_TpNtGz0oUHRdWiY
A99: 95 | B99: 2254028483 | C99: Phùng Minh Thư | D99: S25-64QT-KDQT | E99: 2.71 | F99: Hoàn thiện công tác tuyển dụng nhân sự tại Công ty TNHH KOI Café Việt Nam | H99: =IF(G99=0,F99,G99) -> Hoàn thiện công tác tuyển dụng nhân sự tại Công ty TNHH KOI Café Việt Nam | I99: TS. Hà Kiên Tân | K99: Quản trị kinh doanh quốc tế | L99: Kế toán & Quản trị kinh doanh | M99: =VLOOKUP(B99,Sheet4!D:O,11,0) -> https://drive.google.com/open?id=1W_z06kxXTZZB9um7qs6Oi7hwRESTGTuy
A100: 96 | B100: 2254028467 | C100: Lê Thụy Hồng Quyên | D100: S25-64QT-KDQT | E100: 2.7 | F100: Hoàn thiện hoạt động kinh doanh tại Công ty Cổ phần đầu tư địa ốc Tân Thịnh | H100: =IF(G100=0,F100,G100) -> Hoàn thiện hoạt động kinh doanh tại Công ty Cổ phần đầu tư địa ốc Tân Thịnh | I100: TS. Hà Kiên Tân | K100: Quản trị kinh doanh quốc tế | L100: Kế toán & Quản trị kinh doanh | M100: =VLOOKUP(B100,Sheet4!D:O,11,0) -> https://drive.google.com/open?id=19VHTVQ6wpK0xBC97dPYjmS2S9st8WBTa
A101: 97 | B101: 2254028499 | C101: Bùi Ngọc Lan Vy | D101: S25-64QT-KDQT | E101: 2.61 | F101: Hoàn thiện hoạt động tuyển dụng nhân lực tại Công ty TNHH Redsun Logistics | H101: =IF(G101=0,F101,G101) -> Hoàn thiện hoạt động tuyển dụng nhân lực tại Công ty TNHH Redsun Logistics | I101: TS. Hà Kiên Tân | K101: Quản trị kinh doanh quốc tế | L101: Kế toán & Quản trị kinh doanh | M101: =VLOOKUP(B101,Sheet4!D:O,11,0) -> https://drive.google.com/open?id=11oqq7j6FvyLmlczN-xNQdPprBZ7EdE9l
A102: 98 | B102: 2254028492 | C102: Đẩu Phạm Ngọc Trinh | D102: S25-64QT-KDQT | E102: 2.62 | F102: Hoàn thiện hoạt động tuyển dụng nhân lực tại Công ty Cổ phần giao nhận WinWin | H102: =IF(G102=0,F102,G102) -> Hoàn thiện hoạt động tuyển dụng nhân lực tại Công ty Cổ phần giao nhận WinWin | I102: TS. Hà Kiên Tân | K102: Quản trị kinh doanh quốc tế | L102: Kế toán & Quản trị kinh doanh | M102: =VLOOKUP(B102,Sheet4!D:O,11,0) -> https://drive.google.com/open?id=1k2fzhm-Yms7YLQuUsBqkd9NBts4RfPmp
A103: 99 | B103: 2254028431 | C103: Phạm Ngọc Kim Huệ | D103: S25-64QT-KDQT | E103: 3.08 | F103: Nâng cao hiệu quả quy trình thông quan hàng xuất khẩu bằng đường biển tại Công ty TNHH Thương mại dịch vụ đầu tư Tân Minh Trí | H103: =IF(G103=0,F103,G103) -> Nâng cao hiệu quả quy trình thông quan hàng xuất khẩu bằng đường biển tại Công ty TNHH Thương mại dịch vụ đầu tư Tân Minh Trí | I103: TS. Hà Kiên Tân | K103: Quản trị kinh doanh quốc tế | L103: Kế toán & Quản trị kinh doanh | M103: =VLOOKUP(B103,Sheet4!D:O,11,0) -> https://drive.google.com/open?id=1vsuI7TTtKYJri8ZbTfXpOjgMHADeMa3P
...

Sheet Sheet6
A1: TT | B1: MSV | C1: Họ và tên | D1: Lớp | E1: Cán bộ hướng dẫn | F1: Tên đề tài cũ | G1: Tên đề tài mới
A2: 1 | B2: 2154037769 | C2: Lê Thị Thanh Loan | D2: S24-63KT | E2: Lê Tiến Dũng | F2: Kế toán thanh toán với người bán và người mua tại Công ty Cổ Phần Quốc tế Wing | G2: Kế toán thanh toán với người bán và người mua tại Công ty TNHH DGS Logistics | H2: Có
A3: 2 | B3: 2254038548 | C3: Nguyễn Thị Hồng Phượng | D3: S25-64KT | E3: Lữ Thị Thanh Thúy | F3: Kế toán thanh toán với người mua, người bán tại Công ty TNHH Sunday Basic | G3: Kế toán thanh toán với người mua, người bán tại Công ty TNHH Sunday Basic TNT | H3: Có
A4: 3 | B4: 2254038538 | C4: Trần Thị Bích Ngọc | D4: S25-64KT | E4: Đỗ Thị Thu Thủy | F4: Kế toán thanh toán với người bán, người mua tại Khách sạn Mường Thanh Grand Sài Gòn Centre Hotel | G4: Kế toán thanh toán với người bán, người mua tại Khách sạn Mường Thanh Sài Gòn Centre - Chi Nhánh DNTN Xây dựng số 1 tỉnh Điện Biên | H4: Có
A5: 4 | B5: 2254038551 | C5: Nguyễn Thị Tuyết Quyên | D5: S25-64KT | E5: Đỗ Thị Thu Thủy | F5: Kế toán thanh toán với người bán, người mua tại Công ty Liên doanh Hữu hạn Khách sạn Chains Caravelle | G5: Kế toán thanh toán với người bán, người mua tại Công ty TNHH dịch vụ vận tải biển Vestal | H5: Có
A6: 5 | B6: 2254038518 | C6: Trương Thị Điệp | D6: S25-64KT | E6: Đỗ Thị Thu Thủy | F6: Kế toán thanh toán với người bán, người mua tại Công ty Cổ phần Tập đoàn Đèo Cả | G6: Kế toán thanh toán với người bán, người mua tại Công ty TNHH Thương mại & Xây dựng Phú Hưng Azcons | H6: Có
A7: 6 | B7: 2154027093 | C7: Võ Thị Hồng Hạnh | D7: S24-63QT- MAR | E7: ThS. Tăng Thị Lưu | F7: Giải pháp thúc đẩy hiệu quả hoạt động bán hàng cá nhân của đội ngũ môi giới tại Công Ty CP Đầu Tư Và Dịch Vụ Đất Xanh Miền Nam | G7: Giải pháp thúc đẩy hiệu quả hoạt động bán hàng cá nhân của đội ngũ môi giới tại Công Ty TNHH Tập Đoàn Nam Việt Group | H7: Có
A8: 7 | B8: 2254023910 | C8: Ngô Sỹ Siêu | D8: S25-64QT-KDQT | E8: ThS. Tăng Thị Lưu | F8: Thực trạng và giải pháp nâng cao hiệu quả hoạt động tuyển sinh tại Trường Cao đẳng nghề Hoa Sen | G8: Giải pháp nâng cao hiệu quả hoạt động truyền thông marketing tại Trường Cao đẳng nghề Hoa Sen | H8: Có
A9: 8 | B9: 2254078783 | C9: Bùi Anh Quốc | D9: S25-64LG1 | E9: TS. Trần Thị Thanh Huyền | F9: Thực trạng quy trình giao nhận hàng hóa nhập khẩu hàng nguyên container bằng đường biển tại Công ty Tiến Phát Logistics | G9: Thực trạng quy trình giao nhận hàng nhập khẩu nguyên container bằng đường biển tại Công ty LOGIMEX | H9: Có
A10: 9 | B10: 2254078722 | C10: Vũ Thị Thanh Hương | D10: S25-64LG1 | E10: TS. Trần Thị Thanh Huyền | F10: Hoàn thiện hoạt động phát triển kinh doanh Logistics của Công ty TNHH Hoàng Tường | G10: Hoàn thiện hoạt động phát triển kinh doanh Logistics của Công ty TNHH Vận tải Bách Việt | H10: Có
A11: 10 | B11: 2254078680 | C11: Phạm Thị Kim Dung | D11: S25-64LG1 | E11: TS. Trần Thị Thanh Huyền | F11: Thực trạng và giải pháp hoạt động logistics đầu vào của Công ty Cổ phần 25 FIT | G11: Thực trạng và giải pháp hoạt động mua hàng trong chuỗi cung ứng của Công ty Cổ phần 25 FIT | H11: Có
A12: 11 | B12: 2154077874 | C12: Ngô Nguyên Bình | D12: S24-63LG1 | E12: TS. Hà Kiên Tân | F12: Hoàn thiện quy trình giao nhận hàng hóa xuất khẩu nguyên container tại Công ty TNHH Xuất nhập khẩu Green Ocean | G12: Hoàn thiện quy trình giao nhận hàng hóa xuất khẩu nguyên container tại Công Ty Cổ Phần SME Worldwide Logistics | H12: Có
A13: 12 | B13: 2154077853 | C13: Phạm Minh Quốc | D13: S24-63LG1 | E13: TS. Hà Kiên Tân | F13: Hoàn thiện quy trình xuất khẩu hàng hoá nguyên container bằng đường biển tại Công ty Cổ phần quốc tế Phong Phú | G13: Hoàn thiện quy trình xuất khẩu hàng hoá nguyên container bằng đường biển tại Công ty TNHH Vận tải Miên Sơn | H13: Có
A14: 13 | B14: 2254078767 | C14: Trần Thị Quỳnh Như | D14: S25-64LG2 | E14: TS. Hà Kiên Tân | F14: Nâng cao hiệu quả hoạt động kinh doanh dịch vụ logistics tại Công ty TNHH TMDV XNK Asia Ocean Việt Nam | G14: Hoàn thiện hoạt động dịch vụ vận tải biển của Công ty TNHH Thương mại Dịch vụ Xuất nhập khẩu Asia Ocean Việt Nam | H14: Có

Sheet TH
A1: STT | B1: MSSV | C1: Họ và Tên | D1: Ngày sinh | E1: Ngay sinh CCCD | F1: KT | G1: CCCD | H1: Nơi sinh | I1: Dân tộc | J1: Lớp | K1: Khoá | L1: Số điểm tích lũy | M1: Tên Đề Tài | N1: GV Hướng Dẫn 1 | O1: GV Hướng Dẫn 2 | P1: Ngành | Q1: Bộ Môn | R1: Hệ
A2: 1 | B2: 1951065174 | C2: =VLOOKUP($B2,'DS nhan HPTN'!$B:$L,2,0) -> Hà Lê Duy | D2: =VLOOKUP($B2,'DL DSDV PH'!B:F,5,0) -> 09/04/2001 | E2: =VLOOKUP(B2,Sheet4!D:I,5,0) -> 04/09/2001 | F2: =IF(D2=E2,"T","F") -> F | G2: =VLOOKUP(B2,Sheet4!D:I,6,0) -> 038201001253 | H2: =VLOOKUP($B2,Sheet4!$D:$M,8,0) -> Thanh Hoá | I2: =VLOOKUP($B2,Sheet4!$D:$M,9,0) -> Thái | J2: =VLOOKUP($B2,'DS nhan HPTN'!$B:$L,3,0) -> S22-61TH1 | K2: =VLOOKUP($J2,'DL tạo lớp'!$B:$C,2,0) -> K61 | L2: 2.46 | M2: =VLOOKUP($B2,'DS nhan HPTN'!$B:$L,7,0) -> Xây dựng hệ thống quản lý bán hàng đa nền tảng dựa trên Flutter và Firebase | N2: =VLOOKUP($B2,'DS nhan HPTN'!$B:$L,8,0) -> TS. Hoàng Thị Kiều Anh | O2: 0 | P2: =VLOOKUP($B2,'DS nhan HPTN'!$B:$L,10,0) -> Công nghệ thông tin | Q2: =VLOOKUP($B2,'DS nhan HPTN'!$B:$L,11,0) -> Công nghệ thông tin | R2: Chính quy
A3: 2 | B3: 2051067522 | C3: =VLOOKUP($B3,'DS nhan HPTN'!$B:$L,2,0) -> Nguyễn Ngọc Bảo | D3: =VLOOKUP($B3,'DL DSDV PH'!B:F,5,0) -> 22/12/2002 | E3: =VLOOKUP(B3,Sheet4!D:I,5,0) -> 22/12/2002 | F3: =IF(D3=E3,"T","F") -> T | G3: =VLOOKUP(B3,Sheet4!D:I,6,0) -> 052202012903 | H3: =VLOOKUP($B3,Sheet4!$D:$M,8,0) -> Gia Lai | I3: =VLOOKUP($B3,Sheet4!$D:$M,9,0) -> Kinh | J3: =VLOOKUP($B3,'DS nhan HPTN'!$B:$L,3,0) -> S23-62TH | K3: =VLOOKUP($J3,'DL tạo lớp'!$B:$C,2,0) -> K62 | L3: 2.78 | M3: =VLOOKUP($B3,'DS nhan HPTN'!$B:$L,7,0) -> Xây dựng website định giá Bất động sản tại Thành phố Hồ Chí Minh thông qua kỹ thuật học máy | N3: =VLOOKUP($B3,'DS nhan HPTN'!$B:$L,8,0) -> ThS. Trần Ngọc Dân | O3: 0 | P3: =VLOOKUP($B3,'DS nhan HPTN'!$B:$L,10,0) -> Công nghệ thông tin | Q3: =VLOOKUP($B3,'DS nhan HPTN'!$B:$L,11,0) -> Công nghệ thông tin | R3: Chính quy
A4: 3 | B4: 2151067055 | C4: =VLOOKUP($B4,'DS nhan HPTN'!$B:$L,2,0) -> Chung Gia Bảo | D4: =VLOOKUP($B4,'DL DSDV PH'!B:F,5,0) -> 24/09/2003 | E4: =VLOOKUP(B4,Sheet4!D:I,5,0) -> 24/09/2003 | F4: =IF(D4=E4,"T","F") -> T | G4: =VLOOKUP(B4,Sheet4!D:I,6,0) -> 079203043874 | H4: =VLOOKUP($B4,Sheet4!$D:$M,8,0) -> Vĩnh Long | I4: =VLOOKUP($B4,Sheet4!$D:$M,9,0) -> Kinh | J4: =VLOOKUP($B4,'DS nhan HPTN'!$B:$L,3,0) -> S24-63CNTT1 | K4: =VLOOKUP($J4,'DL tạo lớp'!$B:$C,2,0) -> K63 | L4: 2.15 | M4: =VLOOKUP($B4,'DS nhan HPTN'!$B:$L,7,0) -> Xây dựng hệ thống website Gia Bao kinh doanh thiết bị di động trực tuyến tích hợp quản lý kho và đơn hàng | N4: =VLOOKUP($B4,'DS nhan HPTN'!$B:$L,8,0) -> TS. Hoàng Thị Kiều Anh | O4: 0 | P4: =VLOOKUP($B4,'DS nhan HPTN'!$B:$L,10,0) -> Công nghệ thông tin | Q4: =VLOOKUP($B4,'DS nhan HPTN'!$B:$L,11,0) -> Công nghệ thông tin | R4: Chính quy
A5: 4 | B5: 2151067060 | C5: =VLOOKUP($B5,'DS nhan HPTN'!$B:$L,2,0) -> Võ Hoàn Lạc | D5: =VLOOKUP($B5,'DL DSDV PH'!B:F,5,0) -> 03/11/2003 | E5: =VLOOKUP(B5,Sheet4!D:I,5,0) -> 03/11/2003 | F5: =IF(D5=E5,"T","F") -> T | G5: =VLOOKUP(B5,Sheet4!D:I,6,0) -> 064203000856 | H5: =VLOOKUP($B5,Sheet4!$D:$M,8,0) -> Gia Lai | I5: =VLOOKUP($B5,Sheet4!$D:$M,9,0) -> Kinh | J5: =VLOOKUP($B5,'DS nhan HPTN'!$B:$L,3,0) -> S24-63CNTT1 | K5: =VLOOKUP($J5,'DL tạo lớp'!$B:$C,2,0) -> K63 | L5: 2.21 | M5: =VLOOKUP($B5,'DS nhan HPTN'!$B:$L,7,0) -> Xây dựng website thời trang LaHo tích hợp chatbot hỗ trợ và tư vấn khách hàng | N5: =VLOOKUP($B5,'DS nhan HPTN'!$B:$L,8,0) -> TS. Hoàng Thị Kiều Anh | O5: 0 | P5: =VLOOKUP($B5,'DS nhan HPTN'!$B:$L,10,0) -> Công nghệ thông tin | Q5: =VLOOKUP($B5,'DS nhan HPTN'!$B:$L,11,0) -> Công nghệ thông tin | R5: Chính quy
A6: 5 | B6: 2151067238 | C6: =VLOOKUP($B6,'DS nhan HPTN'!$B:$L,2,0) -> Võ Lê Hậu | D6: =VLOOKUP($B6,'DL DSDV PH'!B:F,5,0) -> 16/02/2003 | E6: =VLOOKUP(B6,Sheet4!D:I,5,0) -> 16/02/2003 | F6: =IF(D6=E6,"T","F") -> T | G6: =VLOOKUP(B6,Sheet4!D:I,6,0) -> 052203016108 | H6: =VLOOKUP($B6,Sheet4!$D:$M,8,0) -> Gia Lai | I6: =VLOOKUP($B6,Sheet4!$D:$M,9,0) -> Kinh | J6: =VLOOKUP($B6,'DS nhan HPTN'!$B:$L,3,0) -> S24-63CNTT1 | K6: =VLOOKUP($J6,'DL tạo lớp'!$B:$C,2,0) -> K63 | L6: 2.18 | M6: =VLOOKUP($B6,'DS nhan HPTN'!$B:$L,7,0) -> Xây dựng ứng dụng quản lý học tại trung tâm giáo dục Thành Công | N6: =VLOOKUP($B6,'DS nhan HPTN'!$B:$L,8,0) -> ThS. Tống Thị Nhung | O6: 0 | P6: =VLOOKUP($B6,'DS nhan HPTN'!$B:$L,10,0) -> Công nghệ thông tin | Q6: =VLOOKUP($B6,'DS nhan HPTN'!$B:$L,11,0) -> Công nghệ thông tin | R6: Chính quy
A7: 6 | B7: 2151067630 | C7: =VLOOKUP($B7,'DS nhan HPTN'!$B:$L,2,0) -> Lê Văn Bảo | D7: =VLOOKUP($B7,'DL DSDV PH'!B:F,5,0) -> 18/08/2003 | E7: =VLOOKUP(B7,Sheet4!D:I,5,0) -> 18/08/2003 | F7: =IF(D7=E7,"T","F") -> T | G7: =VLOOKUP(B7,Sheet4!D:I,6,0) -> 068203009186 | H7: =VLOOKUP($B7,Sheet4!$D:$M,8,0) -> Lâm Đồng | I7: =VLOOKUP($B7,Sheet4!$D:$M,9,0) -> Kinh | J7: =VLOOKUP($B7,'DS nhan HPTN'!$B:$L,3,0) -> S24-63CNTT2 | K7: =VLOOKUP($J7,'DL tạo lớp'!$B:$C,2,0) -> K63 | L7: 2.07 | M7: =VLOOKUP($B7,'DS nhan HPTN'!$B:$L,7,0) -> Thiết kế xây dựng sensor đo và theo dõi độ mặn trong quản lý chất lượng nước | N7: =VLOOKUP($B7,'DS nhan HPTN'!$B:$L,8,0) -> TS. Hoàng Văn Quý | O7: 0 | P7: =VLOOKUP($B7,'DS nhan HPTN'!$B:$L,10,0) -> Công nghệ thông tin | Q7: =VLOOKUP($B7,'DS nhan HPTN'!$B:$L,11,0) -> Công nghệ thông tin | R7: Chính quy
A8: 7 | B8: 2151067620 | C8: =VLOOKUP($B8,'DS nhan HPTN'!$B:$L,2,0) -> Nguyễn Nam Nhân | D8: =VLOOKUP($B8,'DL DSDV PH'!B:F,5,0) -> 23/02/2003 | E8: =VLOOKUP(B8,Sheet4!D:I,5,0) -> 23/02/2003 | F8: =IF(D8=E8,"T","F") -> T | G8: =VLOOKUP(B8,Sheet4!D:I,6,0) -> 054203004471 | H8: =VLOOKUP($B8,Sheet4!$D:$M,8,0) -> Đắk Lắk | I8: =VLOOKUP($B8,Sheet4!$D:$M,9,0) -> Kinh | J8: =VLOOKUP($B8,'DS nhan HPTN'!$B:$L,3,0) -> S24-63CNTT2 | K8: =VLOOKUP($J8,'DL tạo lớp'!$B:$C,2,0) -> K63 | L8: 2.5 | M8: =VLOOKUP($B8,'DS nhan HPTN'!$B:$L,7,0) -> Xây dựng website quản lý kho hàng ứng dụng công nghệ AI | N8: =VLOOKUP($B8,'DS nhan HPTN'!$B:$L,8,0) -> ThS. Trần Ngọc Dân | O8: 0 | P8: =VLOOKUP($B8,'DS nhan HPTN'!$B:$L,10,0) -> Công nghệ thông tin | Q8: =VLOOKUP($B8,'DS nhan HPTN'!$B:$L,11,0) -> Công nghệ thông tin | R8: Chính quy
A9: 8 | B9: 2151067610 | C9: =VLOOKUP($B9,'DS nhan HPTN'!$B:$L,2,0) -> Võ Trần Luân | D9: =VLOOKUP($B9,'DL DSDV PH'!B:F,5,0) -> 03/05/2003 | E9: =VLOOKUP(B9,Sheet4!D:I,5,0) -> 03/05/2003 | F9: =IF(D9=E9,"T","F") -> T | G9: =VLOOKUP(B9,Sheet4!D:I,6,0) -> 072203002752 | H9: =VLOOKUP($B9,Sheet4!$D:$M,8,0) -> Thành phố Hồ Chí Minh | I9: =VLOOKUP($B9,Sheet4!$D:$M,9,0) -> Kinh | J9: =VLOOKUP($B9,'DS nhan HPTN'!$B:$L,3,0) -> S24-63CNTT2 | K9: =VLOOKUP($J9,'DL tạo lớp'!$B:$C,2,0) -> K63 | L9: 2.42 | M9: =VLOOKUP($B9,'DS nhan HPTN'!$B:$L,7,0) -> Thiết kế và xây dựng hệ thống điều khiển nhà thông minh trên nền tảng ESP32S | N9: =VLOOKUP($B9,'DS nhan HPTN'!$B:$L,8,0) -> ThS. Nguyễn Thị Hồng Tú | O9: 0 | P9: =VLOOKUP($B9,'DS nhan HPTN'!$B:$L,10,0) -> Công nghệ thông tin | Q9: =VLOOKUP($B9,'DS nhan HPTN'!$B:$L,11,0) -> Công nghệ thông tin | R9: Chính quy
A10: 9 | B10: 2151067072 | C10: =VLOOKUP($B10,'DS nhan HPTN'!$B:$L,2,0) -> Tăng Phước Sang | D10: =VLOOKUP($B10,'DL DSDV PH'!B:F,5,0) -> 23/01/2003 | E10: =VLOOKUP(B10,Sheet4!D:I,5,0) -> 23/01/2003 | F10: =IF(D10=E10,"T","F") -> T | G10: =VLOOKUP(B10,Sheet4!D:I,6,0) -> 070203003401 | H10: =VLOOKUP($B10,Sheet4!$D:$M,8,0) -> Đồng Nai | I10: =VLOOKUP($B10,Sheet4!$D:$M,9,0) -> Hoa | J10: =VLOOKUP($B10,'DS nhan HPTN'!$B:$L,3,0) -> S24-63CNTT2 | K10: =VLOOKUP($J10,'DL tạo lớp'!$B:$C,2,0) -> K63 | L10: 2.05 | M10: =VLOOKUP($B10,'DS nhan HPTN'!$B:$L,7,0) -> Thiết kế và phát triển website du lịch trực tuyến VietExplore | N10: =VLOOKUP($B10,'DS nhan HPTN'!$B:$L,8,0) -> ThS. Vũ Thị Hạnh | O10: 0 | P10: =VLOOKUP($B10,'DS nhan HPTN'!$B:$L,10,0) -> Công nghệ thông tin | Q10: =VLOOKUP($B10,'DS nhan HPTN'!$B:$L,11,0) -> Công nghệ thông tin | R10: Chính quy
A11: 10 | B11: 2151067053 | C11: =VLOOKUP($B11,'DS nhan HPTN'!$B:$L,2,0) -> Hồ Minh Anh | D11: =VLOOKUP($B11,'DL DSDV PH'!B:F,5,0) -> 20/09/2003 | E11: =VLOOKUP(B11,Sheet4!D:I,5,0) -> 20/09/2003 | F11: =IF(D11=E11,"T","F") -> T | G11: =VLOOKUP(B11,Sheet4!D:I,6,0) -> 087303016224 | H11: =VLOOKUP($B11,Sheet4!$D:$M,8,0) -> Đồng Tháp | I11: =VLOOKUP($B11,Sheet4!$D:$M,9,0) -> Kinh | J11: =VLOOKUP($B11,'DS nhan HPTN'!$B:$L,3,0) -> S24-63CNTT2 | K11: =VLOOKUP($J11,'DL tạo lớp'!$B:$C,2,0) -> K63 | L11: 2.42 | M11: =VLOOKUP($B11,'DS nhan HPTN'!$B:$L,7,0) -> Phát triển ứng dụng di động quản lý sự kiện sử dụng Flutter | N11: =VLOOKUP($B11,'DS nhan HPTN'!$B:$L,8,0) -> ThS. Nguyễn Thị Hồng Tú | O11: 0 | P11: =VLOOKUP($B11,'DS nhan HPTN'!$B:$L,10,0) -> Công nghệ thông tin | Q11: =VLOOKUP($B11,'DS nhan HPTN'!$B:$L,11,0) -> Công nghệ thông tin | R11: Chính quy
A12: 11 | B12: 2151067239 | C12: =VLOOKUP($B12,'DS nhan HPTN'!$B:$L,2,0) -> Đặng Nguyễn Minh Hoàng | D12: =VLOOKUP($B12,'DL DSDV PH'!B:F,5,0) -> 31/03/2003 | E12: =VLOOKUP(B12,Sheet4!D:I,5,0) -> 30/03/2003 | F12: =IF(D12=E12,"T","F") -> F | G12: =VLOOKUP(B12,Sheet4!D:I,6,0) -> 022203000021 | H12: =VLOOKUP($B12,Sheet4!$D:$M,8,0) -> Thành phố Hồ Chí Minh | I12: =VLOOKUP($B12,Sheet4!$D:$M,9,0) -> Kinh | J12: =VLOOKUP($B12,'DS nhan HPTN'!$B:$L,3,0) -> S24-63CNTT2 | K12: =VLOOKUP($J12,'DL tạo lớp'!$B:$C,2,0) -> K63 | L12: 2.42 | M12: =VLOOKUP($B12,'DS nhan HPTN'!$B:$L,7,0) -> Xây dựng website quản lý dự án cho Công ty Vision | N12: =VLOOKUP($B12,'DS nhan HPTN'!$B:$L,8,0) -> ThS. Nguyễn Thị Hồng Tú | O12: 0 | P12: =VLOOKUP($B12,'DS nhan HPTN'!$B:$L,10,0) -> Công nghệ thông tin | Q12: =VLOOKUP($B12,'DS nhan HPTN'!$B:$L,11,0) -> Công nghệ thông tin | R12: Chính quy
A13: 12 | B13: 2251068218 | C13: =VLOOKUP($B13,'DS nhan HPTN'!$B:$L,2,0) -> Lê Võ Nhựt Nguyên | D13: =VLOOKUP($B13,'DL DSDV PH'!B:F,5,0) -> 26/09/2004 | E13: =VLOOKUP(B13,Sheet4!D:I,5,0) -> 26/09/2004 | F13: =IF(D13=E13,"T","F") -> T | G13: =VLOOKUP(B13,Sheet4!D:I,6,0) -> 083204007004 | H13: =VLOOKUP($B13,Sheet4!$D:$M,8,0) -> Vĩnh Long | I13: =VLOOKUP($B13,Sheet4!$D:$M,9,0) -> Kinh | J13: =VLOOKUP($B13,'DS nhan HPTN'!$B:$L,3,0) -> S25-64CNTT | K13: =VLOOKUP($J13,'DL tạo lớp'!$B:$C,2,0) -> K64 | L13: 2.91 | M13: =VLOOKUP($B13,'DS nhan HPTN'!$B:$L,7,0) -> Thiết kế và xây dựng hệ thống IoT giám sát, chống trộm và cảnh báo tai nạn cho xe máy | N13: =VLOOKUP($B13,'DS nhan HPTN'!$B:$L,8,0) -> ThS. Vũ Thị Hạnh | O13: 0 | P13: =VLOOKUP($B13,'DS nhan HPTN'!$B:$L,10,0) -> Công nghệ thông tin | Q13: =VLOOKUP($B13,'DS nhan HPTN'!$B:$L,11,0) -> Công nghệ thông tin | R13: Chính quy
... A194: 193 | B194: 2254038578 | C194: =VLOOKUP($B194,'DS nhan HPTN'!$B:$L,2,0) -> Trần Ngọc Như Ý | D194: =VLOOKUP($B194,'DL DSDV PH'!B:F,5,0) -> 10/11/2004 | E194: =VLOOKUP(B194,Sheet4!D:I,5,0) -> 10/11/2004 | F194: =IF(D194=E194,"T","F") -> T | G194: =VLOOKUP(B194,Sheet4!D:I,6,0) -> 079304014199 | H194: =VLOOKUP($B194,Sheet4!$D:$M,8,0) -> Thành phố Hồ Chí Minh | I194: =VLOOKUP($B194,Sheet4!$D:$M,9,0) -> Kinh | J194: =VLOOKUP($B194,'DS nhan HPTN'!$B:$L,3,0) -> S25-64KT | K194: =VLOOKUP($J194,'DL tạo lớp'!$B:$C,2,0) -> K64 | L194: 3.35 | M194: =VLOOKUP($B194,'DS nhan HPTN'!$B:$L,7,0) -> Kế toán thanh toán với người bán, người mua tại Công ty Cổ phần Thiết Bị Xây Dựng Vina (vinamac) | N194: =VLOOKUP($B194,'DS nhan HPTN'!$B:$L,8,0) -> ThS. Nguyễn Thị Diện | O194: 0 | P194: =VLOOKUP($B194,'DS nhan HPTN'!$B:$L,10,0) -> Kế toán | Q194: =VLOOKUP($B194,'DS nhan HPTN'!$B:$L,11,0) -> Kế toán & Quản trị kinh doanh | R194: Chính quy
A195: 194 | B195: 2254078794 | C195: =VLOOKUP($B195,'DS nhan HPTN'!$B:$L,2,0) -> Nguyễn Mai Sỹ | D195: =VLOOKUP($B195,'DL DSDV PH'!B:F,5,0) -> 15/01/2004 | E195: =VLOOKUP(B195,Sheet4!D:I,5,0) -> 15/01/2004 | F195: =IF(D195=E195,"T","F") -> T | G195: =VLOOKUP(B195,Sheet4!D:I,6,0) -> 054204003261 | H195: =VLOOKUP($B195,Sheet4!$D:$M,8,0) -> Đắk Lắk | I195: =VLOOKUP($B195,Sheet4!$D:$M,9,0) -> Kinh | J195: =VLOOKUP($B195,'DS nhan HPTN'!$B:$L,3,0) -> S25-64LG1 | K195: =VLOOKUP($J195,'DL tạo lớp'!$B:$C,2,0) -> K64 | L195: 2.09 | M195: =VLOOKUP($B195,'DS nhan HPTN'!$B:$L,7,0) -> Thực trạng hoạt động giao nhận hàng hoá bằng đường hàng không tại Công ty TNHH Tiếp Vận Toàn Cầu N.T.D | N195: =VLOOKUP($B195,'DS nhan HPTN'!$B:$L,8,0) -> ThS. Trần Đức Thành | O195: ThS. Phạm Thị Duấn | P195: =VLOOKUP($B195,'DS nhan HPTN'!$B:$L,10,0) -> Logistics và quản lý chuỗi cung ứng | Q195: =VLOOKUP($B195,'DS nhan HPTN'!$B:$L,11,0) -> Kế toán & Quản trị kinh doanh | R195: Chính quy
A196: 195 | B196: 2254078692 | C196: =VLOOKUP($B196,'DS nhan HPTN'!$B:$L,2,0) -> Đào Duy Đức | D196: =VLOOKUP($B196,'DL DSDV PH'!B:F,5,0) -> 18/03/2004 | E196: =VLOOKUP(B196,Sheet4!D:I,5,0) -> 18/03/2004 | F196: =IF(D196=E196,"T","F") -> T | G196: =VLOOKUP(B196,Sheet4!D:I,6,0) -> 052204001708 | H196: =VLOOKUP($B196,Sheet4!$D:$M,8,0) -> Gia Lai | I196: =VLOOKUP($B196,Sheet4!$D:$M,9,0) -> Kinh | J196: =VLOOKUP($B196,'DS nhan HPTN'!$B:$L,3,0) -> S25-64LG1 | K196: =VLOOKUP($J196,'DL tạo lớp'!$B:$C,2,0) -> K64 | L196: 2.68 | M196: =VLOOKUP($B196,'DS nhan HPTN'!$B:$L,7,0) -> Thực trạng hoạt động giao nhận hàng hóa nhập khẩu nguyên container bằng đường biển tại công ty cổ phần giao nhận vận tải Kỳ Lân | N196: =VLOOKUP($B196,'DS nhan HPTN'!$B:$L,8,0) -> ThS. Trần Đức Thành | O196: ThS. Phạm Thị Duấn | P196: =VLOOKUP($B196,'DS nhan HPTN'!$B:$L,10,0) -> Logistics và quản lý chuỗi cung ứng | Q196: =VLOOKUP($B196,'DS nhan HPTN'!$B:$L,11,0) -> Kế toán & Quản trị kinh doanh | R196: Chính quy
A197: 196 | B197: 2254078748 | C197: =VLOOKUP($B197,'DS nhan HPTN'!$B:$L,2,0) -> Huỳnh Thanh Nam | D197: =VLOOKUP($B197,'DL DSDV PH'!B:F,5,0) -> 30/05/2004 | E197: =VLOOKUP(B197,Sheet4!D:I,5,0) -> 30/05/2004 | F197: =IF(D197=E197,"T","F") -> T | G197: =VLOOKUP(B197,Sheet4!D:I,6,0) -> 060204007970 | H197: =VLOOKUP($B197,Sheet4!$D:$M,8,0) -> Lâm Đồng | I197: =VLOOKUP($B197,Sheet4!$D:$M,9,0) -> Kinh | J197: =VLOOKUP($B197,'DS nhan HPTN'!$B:$L,3,0) -> S25-64LG1 | K197: =VLOOKUP($J197,'DL tạo lớp'!$B:$C,2,0) -> K64 | L197: 2.2 | M197: =VLOOKUP($B197,'DS nhan HPTN'!$B:$L,7,0) -> Thực trạng hoạt động giao nhận hàng hóa nhập khẩu bằng đường biển tại Công ty TNHH ONEX Logistics | N197: =VLOOKUP($B197,'DS nhan HPTN'!$B:$L,8,0) -> ThS. Trần Đức Thành | O197: ThS. Phạm Thị Duấn | P197: =VLOOKUP($B197,'DS nhan HPTN'!$B:$L,10,0) -> Logistics và quản lý chuỗi cung ứng | Q197: =VLOOKUP($B197,'DS nhan HPTN'!$B:$L,11,0) -> Kế toán & Quản trị kinh doanh | R197: Chính quy
A198: 197 | B198: 2254078674 | C198: =VLOOKUP($B198,'DS nhan HPTN'!$B:$L,2,0) -> Nguyễn Phạm Xuyến Chi | D198: =VLOOKUP($B198,'DL DSDV PH'!B:F,5,0) -> 25/04/2004 | E198: =VLOOKUP(B198,Sheet4!D:I,5,0) -> 25/04/2004 | F198: =IF(D198=E198,"T","F") -> T | G198: =VLOOKUP(B198,Sheet4!D:I,6,0) -> 038304009339 | H198: =VLOOKUP($B198,Sheet4!$D:$M,8,0) -> Thanh Hoá | I198: =VLOOKUP($B198,Sheet4!$D:$M,9,0) -> Kinh | J198: =VLOOKUP($B198,'DS nhan HPTN'!$B:$L,3,0) -> S25-64LG1 | K198: =VLOOKUP($J198,'DL tạo lớp'!$B:$C,2,0) -> K64 | L198: 2.75 | M198: =VLOOKUP($B198,'DS nhan HPTN'!$B:$L,7,0) -> Một số giải pháp hoàn thiện hoạt động quản lý kho hàng của Công ty TNHH SAI GON HI-TECH | N198: =VLOOKUP($B198,'DS nhan HPTN'!$B:$L,8,0) -> TS. Nguyễn Nam Thắng | O198: 0 | P198: =VLOOKUP($B198,'DS nhan HPTN'!$B:$L,10,0) -> Logistics và quản lý chuỗi cung ứng | Q198: =VLOOKUP($B198,'DS nhan HPTN'!$B:$L,11,0) -> Kế toán & Quản trị kinh doanh | R198: Chính quy
A199: 198 | B199: 2254078776 | C199: =VLOOKUP($B199,'DS nhan HPTN'!$B:$L,2,0) -> Nguyễn Thị Hồng Phúc | D199: =VLOOKUP($B199,'DL DSDV PH'!B:F,5,0) -> 12/07/2004 | E199: =VLOOKUP(B199,Sheet4!D:I,5,0) -> 12/07/2004 | F199: =IF(D199=E199,"T","F") -> T | G199: =VLOOKUP(B199,Sheet4!D:I,6,0) -> 052304001941 | H199: =VLOOKUP($B199,Sheet4!$D:$M,8,0) -> Gia Lai | I199: =VLOOKUP($B199,Sheet4!$D:$M,9,0) -> Kinh | J199: =VLOOKUP($B199,'DS nhan HPTN'!$B:$L,3,0) -> S25-64LG1 | K199: =VLOOKUP($J199,'DL tạo lớp'!$B:$C,2,0) -> K64 | L199: 2.75 | M199: =VLOOKUP($B199,'DS nhan HPTN'!$B:$L,7,0) -> Hoàn thiện hoạt động mua sắm vật tư tại Công ty TNHH Du Thuyền Hoa Sen | N199: =VLOOKUP($B199,'DS nhan HPTN'!$B:$L,8,0) -> ThS. Trần Đức Thành | O199: ThS. Phạm Thị Duấn | P199: =VLOOKUP($B199,'DS nhan HPTN'!$B:$L,10,0) -> Logistics và quản lý chuỗi cung ứng | Q199: =VLOOKUP($B199,'DS nhan HPTN'!$B:$L,11,0) -> Kế toán & Quản trị kinh doanh | R199: Chính quy
A200: 199 | B200: 2254078810 | C200: =VLOOKUP($B200,'DS nhan HPTN'!$B:$L,2,0) -> Trần Ngọc Thảo Thy | D200: =VLOOKUP($B200,'DL DSDV PH'!B:F,5,0) -> 16/09/2004 | E200: =VLOOKUP(B200,Sheet4!D:I,5,0) -> 16/09/2004 | F200: =IF(D200=E200,"T","F") -> T | G200: =VLOOKUP(B200,Sheet4!D:I,6,0) -> 082304000399 | H200: =VLOOKUP($B200,Sheet4!$D:$M,8,0) -> Đồng Tháp | I200: =VLOOKUP($B200,Sheet4!$D:$M,9,0) -> Kinh | J200: =VLOOKUP($B200,'DS nhan HPTN'!$B:$L,3,0) -> S25-64LG1 | K200: =VLOOKUP($J200,'DL tạo lớp'!$B:$C,2,0) -> K64 | L200: 3.03 | M200: =VLOOKUP($B200,'DS nhan HPTN'!$B:$L,7,0) -> Hoàn thiện hoạt động Logistics đầu ra tại Công ty TNHH Tân Sao Á | N200: =VLOOKUP($B200,'DS nhan HPTN'!$B:$L,8,0) -> TS. Trần Văn Biên | O200: 0 | P200: =VLOOKUP($B200,'DS nhan HPTN'!$B:$L,10,0) -> Logistics và quản lý chuỗi cung ứng | Q200: =VLOOKUP($B200,'DS nhan HPTN'!$B:$L,11,0) -> Kế toán & Quản trị kinh doanh | R200: Chính quy
A201: 200 | B201: 2254078846 | C201: =VLOOKUP($B201,'DS nhan HPTN'!$B:$L,2,0) -> Đỗ Nguyễn Như Yến | D201: =VLOOKUP($B201,'DL DSDV PH'!B:F,5,0) -> 17/08/2004 | E201: =VLOOKUP(B201,Sheet4!D:I,5,0) -> 17/08/2004 | F201: =IF(D201=E201,"T","F") -> T | G201: =VLOOKUP(B201,Sheet4!D:I,6,0) -> 052304006600 | H201: =VLOOKUP($B201,Sheet4!$D:$M,8,0) -> Gia Lai | I201: =VLOOKUP($B201,Sheet4!$D:$M,9,0) -> Kinh | J201: =VLOOKUP($B201,'DS nhan HPTN'!$B:$L,3,0) -> S25-64LG1 | K201: =VLOOKUP($J201,'DL tạo lớp'!$B:$C,2,0) -> K64 | L201: 3.3 | M201: =VLOOKUP($B201,'DS nhan HPTN'!$B:$L,7,0) -> Phân tích hoạt động nhập khẩu bằng đường hàng không tại Công ty TNHH Vận tải Miên Sơn | N201: =VLOOKUP($B201,'DS nhan HPTN'!$B:$L,8,0) -> TS. Trần Văn Biên | O201: 0 | P201: =VLOOKUP($B201,'DS nhan HPTN'!$B:$L,10,0) -> Logistics và quản lý chuỗi cung ứng | Q201: =VLOOKUP($B201,'DS nhan HPTN'!$B:$L,11,0) -> Kế toán & Quản trị kinh doanh | R201: Chính quy
A202: 201 | B202: 2254078714 | C202: =VLOOKUP($B202,'DS nhan HPTN'!$B:$L,2,0) -> Trần Thị Thu Hoài | D202: =VLOOKUP($B202,'DL DSDV PH'!B:F,5,0) -> 17/11/2004 | E202: =VLOOKUP(B202,Sheet4!D:I,5,0) -> 17/11/2004 | F202: =IF(D202=E202,"T","F") -> T | G202: =VLOOKUP(B202,Sheet4!D:I,6,0) -> 052304013089 | H202: =VLOOKUP($B202,Sheet4!$D:$M,8,0) -> Gia Lai | I202: =VLOOKUP($B202,Sheet4!$D:$M,9,0) -> Kinh | J202: =VLOOKUP($B202,'DS nhan HPTN'!$B:$L,3,0) -> S25-64LG1 | K202: =VLOOKUP($J202,'DL tạo lớp'!$B:$C,2,0) -> K64 | L202: 2.59 | M202: =VLOOKUP($B202,'DS nhan HPTN'!$B:$L,7,0) -> Tổng hợp phân tích đánh giá hoạt động nhập khẩu bằng đường hàng không tại Công ty TNHH Pungkook Sài Gòn II | N202: =VLOOKUP($B202,'DS nhan HPTN'!$B:$L,8,0) -> TS. Nguyễn Nam Thắng | O202: 0 | P202: =VLOOKUP($B202,'DS nhan HPTN'!$B:$L,10,0) -> Logistics và quản lý chuỗi cung ứng | Q202: =VLOOKUP($B202,'DS nhan HPTN'!$B:$L,11,0) -> Kế toán & Quản trị kinh doanh | R202: Chính quy
A203: 202 | B203: 2254078806 | C203: =VLOOKUP($B203,'DS nhan HPTN'!$B:$L,2,0) -> Nguyễn Diễm Thư | D203: =VLOOKUP($B203,'DL DSDV PH'!B:F,5,0) -> 01/01/2004 | E203: =VLOOKUP(B203,Sheet4!D:I,5,0) -> 01/01/2004 | F203: =IF(D203=E203,"T","F") -> T | G203: =VLOOKUP(B203,Sheet4!D:I,6,0) -> 046304012646 | H203: =VLOOKUP($B203,Sheet4!$D:$M,8,0) -> Huế | I203: =VLOOKUP($B203,Sheet4!$D:$M,9,0) -> Kinh | J203: =VLOOKUP($B203,'DS nhan HPTN'!$B:$L,3,0) -> S25-64LG1 | K203: =VLOOKUP($J203,'DL tạo lớp'!$B:$C,2,0) -> K64 | L203: 3.11 | M203: =VLOOKUP($B203,'DS nhan HPTN'!$B:$L,7,0) -> Giải pháp mở rộng thị trường dịch vụ logistics quốc tế tại Công ty cổ phần Giao nhận vận tải Kỳ Lân | N203: =VLOOKUP($B203,'DS nhan HPTN'!$B:$L,8,0) -> ThS. Trần Đức Thành | O203: ThS. Phạm Thị Duấn | P203: =VLOOKUP($B203,'DS nhan HPTN'!$B:$L,10,0) -> Logistics và quản lý chuỗi cung ứng | Q203: =VLOOKUP($B203,'DS nhan HPTN'!$B:$L,11,0) -> Kế toán & Quản trị kinh doanh | R203: Chính quy
A204: 203 | B204: 2254078764 | C204: =VLOOKUP($B204,'DS nhan HPTN'!$B:$L,2,0) -> Nguyễn Ngọc Nhị | D204: =VLOOKUP($B204,'DL DSDV PH'!B:F,5,0) -> 23/09/2004 | E204: =VLOOKUP(B204,Sheet4!D:I,5,0) -> 23/09/2004 | F204: =IF(D204=E204,"T","F") -> T | G204: =VLOOKUP(B204,Sheet4!D:I,6,0) -> 060304004238 | H204: =VLOOKUP($B204,Sheet4!$D:$M,8,0) -> Lâm Đồng | I204: =VLOOKUP($B204,Sheet4!$D:$M,9,0) -> Kinh | J204: =VLOOKUP($B204,'DS nhan HPTN'!$B:$L,3,0) -> S25-64LG1 | K204: =VLOOKUP($J204,'DL tạo lớp'!$B:$C,2,0) -> K64 | L204: 2.85 | M204: =VLOOKUP($B204,'DS nhan HPTN'!$B:$L,7,0) -> Một số giải pháp nâng cao hiệu quả trong hoạt động giao nhận hàng hóa nội địa tại Công ty TNHH Một Thành Viên Chuyển Phát Nhanh Thuận Phong | N204: =VLOOKUP($B204,'DS nhan HPTN'!$B:$L,8,0) -> TS. Nguyễn Nam Thắng | O204: 0 | P204: =VLOOKUP($B204,'DS nhan HPTN'!$B:$L,10,0) -> Logistics và quản lý chuỗi cung ứng | Q204: =VLOOKUP($B204,'DS nhan HPTN'!$B:$L,11,0) -> Kế toán & Quản trị kinh doanh | R204: Chính quy
A205: 204 | B205: 2254078694 | C205: =VLOOKUP($B205,'DS nhan HPTN'!$B:$L,2,0) -> Nguyễn Trần Đức | D205: =VLOOKUP($B205,'DL DSDV PH'!B:F,5,0) -> 26/03/2004 | E205: =VLOOKUP(B205,Sheet4!D:I,5,0) -> 26/03/2004 | F205: =IF(D205=E205,"T","F") -> T | G205: =VLOOKUP(B205,Sheet4!D:I,6,0) -> 064204003961 | H205: =VLOOKUP($B205,Sheet4!$D:$M,8,0) -> Gia Lai | I205: =VLOOKUP($B205,Sheet4!$D:$M,9,0) -> Kinh | J205: =VLOOKUP($B205,'DS nhan HPTN'!$B:$L,3,0) -> S25-64LG1 | K205: =VLOOKUP($J205,'DL tạo lớp'!$B:$C,2,0) -> K64 | L205: 2.45 | M205: =VLOOKUP($B205,'DS nhan HPTN'!$B:$L,7,0) -> Một số giải pháp nâng cao hiệu quả công việc nhân viên tại Công ty TNHH thương mại dịch vụ giao nhận An Thành Phát | N205: =VLOOKUP($B205,'DS nhan HPTN'!$B:$L,8,0) -> TS. Nguyễn Nam Thắng | O205: 0 | P205: =VLOOKUP($B205,'DS nhan HPTN'!$B:$L,10,0) -> Logistics và quản lý chuỗi cung ứng | Q205: =VLOOKUP($B205,'DS nhan HPTN'!$B:$L,11,0) -> Kế toán & Quản trị kinh doanh | R205: Chính quy
A206: 205 | B206: 2254078744 | C206: =VLOOKUP($B206,'DS nhan HPTN'!$B:$L,2,0) -> Phạm Thị Mến | D206: =VLOOKUP($B206,'DL DSDV PH'!B:F,5,0) -> 02/06/2004 | E206: =VLOOKUP(B206,Sheet4!D:I,5,0) -> 02/06/2004 | F206: =IF(D206=E206,"T","F") -> T | G206: =VLOOKUP(B206,Sheet4!D:I,6,0) -> 052304014693 | H206: =VLOOKUP($B206,Sheet4!$D:$M,8,0) -> Gia Lai | I206: =VLOOKUP($B206,Sheet4!$D:$M,9,0) -> Kinh | J206: =VLOOKUP($B206,'DS nhan HPTN'!$B:$L,3,0) -> S25-64LG1 | K206: =VLOOKUP($J206,'DL tạo lớp'!$B:$C,2,0) -> K64 | L206: 3.42 | M206: =VLOOKUP($B206,'DS nhan HPTN'!$B:$L,7,0) -> Thúc đẩy hoạt động chuyển giao công nghệ trong lĩnh vực vận tải của Công ty Cổ phần giải pháp chuỗi cung ứng smartlog | N206: =VLOOKUP($B206,'DS nhan HPTN'!$B:$L,8,0) -> TS. Trần Văn Biên | O206: 0 | P206: =VLOOKUP($B206,'DS nhan HPTN'!$B:$L,10,0) -> Logistics và quản lý chuỗi cung ứng | Q206: =VLOOKUP($B206,'DS nhan HPTN'!$B:$L,11,0) -> Kế toán & Quản trị kinh doanh | R206: Chính quy
A207: 206 | B207: 2254078682 | C207: =VLOOKUP($B207,'DS nhan HPTN'!$B:$L,2,0) -> Trần Văn Dũng | D207: =VLOOKUP($B207,'DL DSDV PH'!B:F,5,0) -> 11/09/2004 | E207: =VLOOKUP(B207,Sheet4!D:I,5,0) -> 11/09/2004 | F207: =IF(D207=E207,"T","F") -> T | G207: =VLOOKUP(B207,Sheet4!D:I,6,0) -> 066204014277 | H207: =VLOOKUP($B207,Sheet4!$D:$M,8,0) -> Đắk Lắk | I207: =VLOOKUP($B207,Sheet4!$D:$M,9,0) -> Kinh | J207: =VLOOKUP($B207,'DS nhan HPTN'!$B:$L,3,0) -> S25-64LG1 | K207: =VLOOKUP($J207,'DL tạo lớp'!$B:$C,2,0) -> K64 | L207: 2.71 | M207: =VLOOKUP($B207,'DS nhan HPTN'!$B:$L,7,0) -> Một số giải pháp nâng cao hiệu quả hoạt động dịch vụ xử lý chứng từ tại Công ty TNHH Tiếp vận và Vận tải Á Âu. | N207: =VLOOKUP($B207,'DS nhan HPTN'!$B:$L,8,0) -> TS. Nguyễn Nam Thắng | O207: 0 | P207: =VLOOKUP($B207,'DS nhan HPTN'!$B:$L,10,0) -> Logistics và quản lý chuỗi cung ứng | Q207: =VLOOKUP($B207,'DS nhan HPTN'!$B:$L,11,0) -> Kế toán & Quản trị kinh doanh | R207: Chính quy
A208: 207 | B208: 2254078758 | C208: =VLOOKUP($B208,'DS nhan HPTN'!$B:$L,2,0) -> Trần Quang Nhật | D208: =VLOOKUP($B208,'DL DSDV PH'!B:F,5,0) -> 19/06/2004 | E208: =VLOOKUP(B208,Sheet4!D:I,5,0) -> 19/06/2004 | F208: =IF(D208=E208,"T","F") -> T | G208: =VLOOKUP(B208,Sheet4!D:I,6,0) -> 068204013864 | H208: =VLOOKUP($B208,Sheet4!$D:$M,8,0) -> Lâm Đồng | I208: =VLOOKUP($B208,Sheet4!$D:$M,9,0) -> Kinh | J208: =VLOOKUP($B208,'DS nhan HPTN'!$B:$L,3,0) -> S25-64LG1 | K208: =VLOOKUP($J208,'DL tạo lớp'!$B:$C,2,0) -> K64 | L208: 2.93 | M208: =VLOOKUP($B208,'DS nhan HPTN'!$B:$L,7,0) -> Một số giải pháp góp phần hoàn thiện hoạt động vận tải quốc tế hàng container bằng đường bộ tại Công ty Cổ phần Tiếp vận Quốc tế Cảng Cát Lái | N208: =VLOOKUP($B208,'DS nhan HPTN'!$B:$L,8,0) -> TS. Nguyễn Nam Thắng | O208: 0 | P208: =VLOOKUP($B208,'DS nhan HPTN'!$B:$L,10,0) -> Logistics và quản lý chuỗi cung ứng | Q208: =VLOOKUP($B208,'DS nhan HPTN'!$B:$L,11,0) -> Kế toán & Quản trị kinh doanh | R208: Chính quy
A209: 208 | B209: 2254078699 | C209: =VLOOKUP($B209,'DS nhan HPTN'!$B:$L,2,0) -> Lương Thị Hằng | D209: =VLOOKUP($B209,'DL DSDV PH'!B:F,5,0) -> 22/11/2003 | E209: =VLOOKUP(B209,Sheet4!D:I,5,0) -> 22/11/2003 | F209: =IF(D209=E209,"T","F") -> T | G209: =VLOOKUP(B209,Sheet4!D:I,6,0) -> 068303006753 | H209: =VLOOKUP($B209,Sheet4!$D:$M,8,0) -> Lâm Đồng | I209: =VLOOKUP($B209,Sheet4!$D:$M,9,0) -> Kinh | J209: =VLOOKUP($B209,'DS nhan HPTN'!$B:$L,3,0) -> S25-64LG1 | K209: =VLOOKUP($J209,'DL tạo lớp'!$B:$C,2,0) -> K64 | L209: 3.24 | M209: =VLOOKUP($B209,'DS nhan HPTN'!$B:$L,7,0) -> Phát triển hoạt động kinh doanh của Công ty TNHH Giải pháp Hàng hải Quốc tế Bình Phú | N209: =VLOOKUP($B209,'DS nhan HPTN'!$B:$L,8,0) -> TS. Trần Văn Biên | O209: 0 | P209: =VLOOKUP($B209,'DS nhan HPTN'!$B:$L,10,0) -> Logistics và quản lý chuỗi cung ứng | Q209: =VLOOKUP($B209,'DS nhan HPTN'!$B:$L,11,0) -> Kế toán & Quản trị kinh doanh | R209: Chính quy
A210: 209 | B210: 2254078797 | C210: =VLOOKUP($B210,'DS nhan HPTN'!$B:$L,2,0) -> Phạm Nguyên Thành | D210: =VLOOKUP($B210,'DL DSDV PH'!B:F,5,0) -> 25/08/2004 | E210: =VLOOKUP(B210,Sheet4!D:I,5,0) -> 25/08/2004 | F210: =IF(D210=E210,"T","F") -> T | G210: =VLOOKUP(B210,Sheet4!D:I,6,0) -> 042204014621 | H210: =VLOOKUP($B210,Sheet4!$D:$M,8,0) -> Hà Tĩnh | I210: =VLOOKUP($B210,Sheet4!$D:$M,9,0) -> Kinh | J210: =VLOOKUP($B210,'DS nhan HPTN'!$B:$L,3,0) -> S25-64LG2 | K210: =VLOOKUP($J210,'DL tạo lớp'!$B:$C,2,0) -> K64 | L210: 2.57 | M210: =VLOOKUP($B210,'DS nhan HPTN'!$B:$L,7,0) -> Nghiên cứu phát triển hoạt động vận tải đường bộ tại Công ty Cổ phần Tiếp vận HNL | N210: =VLOOKUP($B210,'DS nhan HPTN'!$B:$L,8,0) -> TS. Nguyễn Nam Thắng | O210: 0 | P210: =VLOOKUP($B210,'DS nhan HPTN'!$B:$L,10,0) -> Logistics và quản lý chuỗi cung ứng | Q210: =VLOOKUP($B210,'DS nhan HPTN'!$B:$L,11,0) -> Kế toán & Quản trị kinh doanh | R210: Chính quy
A211: 210 | B211: 2254078787 | C211: =VLOOKUP($B211,'DS nhan HPTN'!$B:$L,2,0) -> Hồ Thị Như Quỳnh | D211: =VLOOKUP($B211,'DL DSDV PH'!B:F,5,0) -> 24/08/2004 | E211: =VLOOKUP(B211,Sheet4!D:I,5,0) -> 24/08/2004 | F211: =IF(D211=E211,"T","F") -> T | G211: =VLOOKUP(B211,Sheet4!D:I,6,0) -> 054304002561 | H211: =VLOOKUP($B211,Sheet4!$D:$M,8,0) -> Đắk Lắk | I211: =VLOOKUP($B211,Sheet4!$D:$M,9,0) -> Kinh | J211: =VLOOKUP($B211,'DS nhan HPTN'!$B:$L,3,0) -> S25-64LG2 | K211: =VLOOKUP($J211,'DL tạo lớp'!$B:$C,2,0) -> K64 | L211: 2.54 | M211: =VLOOKUP($B211,'DS nhan HPTN'!$B:$L,7,0) -> Hoàn thiện quy trình khai báo hải quan tại Công ty Cổ phần Logistics Cái Mép | N211: =VLOOKUP($B211,'DS nhan HPTN'!$B:$L,8,0) -> TS. Nguyễn Nam Thắng | O211: 0 | P211: =VLOOKUP($B211,'DS nhan HPTN'!$B:$L,10,0) -> Logistics và quản lý chuỗi cung ứng | Q211: =VLOOKUP($B211,'DS nhan HPTN'!$B:$L,11,0) -> Kế toán & Quản trị kinh doanh | R211: Chính quy
A212: 211 | B212: 2254078701 | C212: =VLOOKUP($B212,'DS nhan HPTN'!$B:$L,2,0) -> Chung Gia Hân | D212: =VLOOKUP($B212,'DL DSDV PH'!B:F,5,0) -> 26/03/2004 | E212: =VLOOKUP(B212,Sheet4!D:I,5,0) -> 26/03/2004 | F212: =IF(D212=E212,"T","F") -> T | G212: =VLOOKUP(B212,Sheet4!D:I,6,0) -> 079304028494 | H212: =VLOOKUP($B212,Sheet4!$D:$M,8,0) -> Thành phố Hồ Chí Minh | I212: =VLOOKUP($B212,Sheet4!$D:$M,9,0) -> Kinh | J212: =VLOOKUP($B212,'DS nhan HPTN'!$B:$L,3,0) -> S25-64LG2 | K212: =VLOOKUP($J212,'DL tạo lớp'!$B:$C,2,0) -> K64 | L212: 2.65 | M212: =VLOOKUP($B212,'DS nhan HPTN'!$B:$L,7,0) -> Phân tích thực trạng thu mua hàng hoá tại Công ty TNHH Apeiron Bionenergy Việt Nam | N212: =VLOOKUP($B212,'DS nhan HPTN'!$B:$L,8,0) -> TS. Trần Văn Biên | O212: 0 | P212: =VLOOKUP($B212,'DS nhan HPTN'!$B:$L,10,0) -> Logistics và quản lý chuỗi cung ứng | Q212: =VLOOKUP($B212,'DS nhan HPTN'!$B:$L,11,0) -> Kế toán & Quản trị kinh doanh | R212: Chính quy
A213: 212 | B213: 2254078839 | C213: =VLOOKUP($B213,'DS nhan HPTN'!$B:$L,2,0) -> Trần Nguyễn Phương Uyên | D213: =VLOOKUP($B213,'DL DSDV PH'!B:F,5,0) -> 05/12/2004 | E213: =VLOOKUP(B213,Sheet4!D:I,5,0) -> 05/12/2004 | F213: =IF(D213=E213,"T","F") -> T | G213: =VLOOKUP(B213,Sheet4!D:I,6,0) -> 077304001725 | H213: =VLOOKUP($B213,Sheet4!$D:$M,8,0) -> Thành phố Hồ Chí Minh | I213: =VLOOKUP($B213,Sheet4!$D:$M,9,0) -> Kinh | J213: =VLOOKUP($B213,'DS nhan HPTN'!$B:$L,3,0) -> S25-64LG2 | K213: =VLOOKUP($J213,'DL tạo lớp'!$B:$C,2,0) -> K64 | L213: 2.18 | M213: =VLOOKUP($B213,'DS nhan HPTN'!$B:$L,7,0) -> Tổng hợp phân tích đánh giá hoạt động xuất khẩu hàng hóa tại Công ty TNHH Thương mại Xuất Nhập Khẩu Phúc Nam Khang | N213: =VLOOKUP($B213,'DS nhan HPTN'!$B:$L,8,0) -> TS. Nguyễn Nam Thắng | O213: 0 | P213: =VLOOKUP($B213,'DS nhan HPTN'!$B:$L,10,0) -> Logistics và quản lý chuỗi cung ứng | Q213: =VLOOKUP($B213,'DS nhan HPTN'!$B:$L,11,0) -> Kế toán & Quản trị kinh doanh | R213: Chính quy
A214: 213 | B214: 2254078745 | C214: =VLOOKUP($B214,'DS nhan HPTN'!$B:$L,2,0) -> Trần Ngọc Mi | D214: =VLOOKUP($B214,'DL DSDV PH'!B:F,5,0) -> 28/01/2004 | E214: =VLOOKUP(B214,Sheet4!D:I,5,0) -> 28/01/2004 | F214: =IF(D214=E214,"T","F") -> T | G214: =VLOOKUP(B214,Sheet4!D:I,6,0) -> 054304007566 | H214: =VLOOKUP($B214,Sheet4!$D:$M,8,0) -> Đắk Lắk | I214: =VLOOKUP($B214,Sheet4!$D:$M,9,0) -> Kinh | J214: =VLOOKUP($B214,'DS nhan HPTN'!$B:$L,3,0) -> S25-64LG2 | K214: =VLOOKUP($J214,'DL tạo lớp'!$B:$C,2,0) -> K64 | L214: 3.27 | M214: =VLOOKUP($B214,'DS nhan HPTN'!$B:$L,7,0) -> Hoàn thiện hoạt động logistics đầu vào của Công ty Cổ phần Đầu tư và Phát triển Dịch vụ CitiGym | N214: =VLOOKUP($B214,'DS nhan HPTN'!$B:$L,8,0) -> TS. Trần Văn Biên | O214: 0 | P214: =VLOOKUP($B214,'DS nhan HPTN'!$B:$L,10,0) -> Logistics và quản lý chuỗi cung ứng | Q214: =VLOOKUP($B214,'DS nhan HPTN'!$B:$L,11,0) -> Kế toán & Quản trị kinh doanh | R214: Chính quy
A215: 214 | B215: 2254078675 | C215: =VLOOKUP($B215,'DS nhan HPTN'!$B:$L,2,0) -> Phạm Thị Kim Chi | D215: =VLOOKUP($B215,'DL DSDV PH'!B:F,5,0) -> 27/11/2004 | E215: =VLOOKUP(B215,Sheet4!D:I,5,0) -> 27/11/2004 | F215: =IF(D215=E215,"T","F") -> T | G215: =VLOOKUP(B215,Sheet4!D:I,6,0) -> 077304002558 | H215: =VLOOKUP($B215,Sheet4!$D:$M,8,0) -> Thành phố Hồ Chí Minh | I215: =VLOOKUP($B215,Sheet4!$D:$M,9,0) -> Kinh | J215: =VLOOKUP($B215,'DS nhan HPTN'!$B:$L,3,0) -> S25-64LG2 | K215: =VLOOKUP($J215,'DL tạo lớp'!$B:$C,2,0) -> K64 | L215: 2.2 | M215: =VLOOKUP($B215,'DS nhan HPTN'!$B:$L,7,0) -> Phát triển hoạt động thu mua hàng hoá tại Công ty Cổ phần Văn hóa Nhân Văn. | N215: =VLOOKUP($B215,'DS nhan HPTN'!$B:$L,8,0) -> ThS. Trần Đức Thành | O215: ThS. Phạm Thị Duấn | P215: =VLOOKUP($B215,'DS nhan HPTN'!$B:$L,10,0) -> Logistics và quản lý chuỗi cung ứng | Q215: =VLOOKUP($B215,'DS nhan HPTN'!$B:$L,11,0) -> Kế toán & Quản trị kinh doanh | R215: Chính quy
A216: 215 | B216: 2254078679 | C216: =VLOOKUP($B216,'DS nhan HPTN'!$B:$L,2,0) -> Nguyễn Thụy Mỹ Dung | D216: =VLOOKUP($B216,'DL DSDV PH'!B:F,5,0) -> 04/09/2004 | E216: =VLOOKUP(B216,Sheet4!D:I,5,0) -> 04/09/2004 | F216: =IF(D216=E216,"T","F") -> T | G216: =VLOOKUP(B216,Sheet4!D:I,6,0) -> 079304012706 | H216: =VLOOKUP($B216,Sheet4!$D:$M,8,0) -> Thành phố Hồ Chí Minh | I216: =VLOOKUP($B216,Sheet4!$D:$M,9,0) -> Kinh | J216: =VLOOKUP($B216,'DS nhan HPTN'!$B:$L,3,0) -> S25-64LG2 | K216: =VLOOKUP($J216,'DL tạo lớp'!$B:$C,2,0) -> K64 | L216: 2.76 | M216: =VLOOKUP($B216,'DS nhan HPTN'!$B:$L,7,0) -> Nâng cao hoạt động quản lý kho lạnh tại Công ty TNHH Thương mại Dịch vụ Quốc tế Hoàn Vũ | N216: =VLOOKUP($B216,'DS nhan HPTN'!$B:$L,8,0) -> TS. Trần Văn Biên | O216: 0 | P216: =VLOOKUP($B216,'DS nhan HPTN'!$B:$L,10,0) -> Logistics và quản lý chuỗi cung ứng | Q216: =VLOOKUP($B216,'DS nhan HPTN'!$B:$L,11,0) -> Kế toán & Quản trị kinh doanh | R216: Chính quy
A217: 216 | B217: 2254078747 | C217: =VLOOKUP($B217,'DS nhan HPTN'!$B:$L,2,0) -> Đỗ Minh Nam | D217: =VLOOKUP($B217,'DL DSDV PH'!B:F,5,0) -> 24/01/2004 | E217: =VLOOKUP(B217,Sheet4!D:I,5,0) -> 24/01/2004 | F217: =IF(D217=E217,"T","F") -> T | G217: =VLOOKUP(B217,Sheet4!D:I,6,0) -> 052204011303 | H217: =VLOOKUP($B217,Sheet4!$D:$M,8,0) -> Quãng Ngãi | I217: =VLOOKUP($B217,Sheet4!$D:$M,9,0) -> Kinh | J217: =VLOOKUP($B217,'DS nhan HPTN'!$B:$L,3,0) -> S25-64LG2 | K217: =VLOOKUP($J217,'DL tạo lớp'!$B:$C,2,0) -> K64 | L217: 1.87 | M217: =VLOOKUP($B217,'DS nhan HPTN'!$B:$L,7,0) -> Tổ chức nghiệp vụ giao nhận hàng xuất khẩu nguyên container bằng đường biển tại Công ty TNHH Tiếp vận Hàng hoá LEGEND | N217: =VLOOKUP($B217,'DS nhan HPTN'!$B:$L,8,0) -> TS. Nguyễn Nam Thắng | O217: 0 | P217: =VLOOKUP($B217,'DS nhan HPTN'!$B:$L,10,0) -> Logistics và quản lý chuỗi cung ứng | Q217: =VLOOKUP($B217,'DS nhan HPTN'!$B:$L,11,0) -> Kế toán & Quản trị kinh doanh | R217: Chính quy
A218: 217 | B218: 2254078835 | C218: =VLOOKUP($B218,'DS nhan HPTN'!$B:$L,2,0) -> Lê Thị Mỹ Tuyên | D218: =VLOOKUP($B218,'DL DSDV PH'!B:F,5,0) -> 12/02/2004 | E218: =VLOOKUP(B218,Sheet4!D:I,5,0) -> 12/02/2004 | F218: =IF(D218=E218,"T","F") -> T | G218: =VLOOKUP(B218,Sheet4!D:I,6,0) -> 058304007429 | H218: =VLOOKUP($B218,Sheet4!$D:$M,8,0) -> Ninh Thuận | I218: =VLOOKUP($B218,Sheet4!$D:$M,9,0) -> Kinh | J218: =VLOOKUP($B218,'DS nhan HPTN'!$B:$L,3,0) -> S25-64LG2 | K218: =VLOOKUP($J218,'DL tạo lớp'!$B:$C,2,0) -> K64 | L218: 2.28 | M218: =VLOOKUP($B218,'DS nhan HPTN'!$B:$L,7,0) -> Một số yếu tố ảnh hưởng đến sự hài lòng của khách hàng đối với dịch vụ nhập khẩu tại Công ty TNHH Cảng Phước Long | N218: =VLOOKUP($B218,'DS nhan HPTN'!$B:$L,8,0) -> TS. Nguyễn Nam Thắng | O218: 0 | P218: =VLOOKUP($B218,'DS nhan HPTN'!$B:$L,10,0) -> Logistics và quản lý chuỗi cung ứng | Q218: =VLOOKUP($B218,'DS nhan HPTN'!$B:$L,11,0) -> Kế toán & Quản trị kinh doanh | R218: Chính quy
A219: 218 | B219: 2254078841 | C219: =VLOOKUP($B219,'DS nhan HPTN'!$B:$L,2,0) -> Ngô Thị Tường Vi | D219: =VLOOKUP($B219,'DL DSDV PH'!B:F,5,0) -> 10/08/2004 | E219: =VLOOKUP(B219,Sheet4!D:I,5,0) -> 10/08/2004 | F219: =IF(D219=E219,"T","F") -> T | G219: =VLOOKUP(B219,Sheet4!D:I,6,0) -> 087304015794 | H219: =VLOOKUP($B219,Sheet4!$D:$M,8,0) -> Đồng Tháp | I219: =VLOOKUP($B219,Sheet4!$D:$M,9,0) -> Kinh | J219: =VLOOKUP($B219,'DS nhan HPTN'!$B:$L,3,0) -> S25-64LG2 | K219: =VLOOKUP($J219,'DL tạo lớp'!$B:$C,2,0) -> K64 | L219: 3.3 | M219: =VLOOKUP($B219,'DS nhan HPTN'!$B:$L,7,0) -> Hoàn thiện hoạt động quản lý kho tại Công ty TNHH Tân Sao Á | N219: =VLOOKUP($B219,'DS nhan HPTN'!$B:$L,8,0) -> TS. Trần Văn Biên | O219: 0 | P219: =VLOOKUP($B219,'DS nhan HPTN'!$B:$L,10,0) -> Logistics và quản lý chuỗi cung ứng | Q219: =VLOOKUP($B219,'DS nhan HPTN'!$B:$L,11,0) -> Kế toán & Quản trị kinh doanh | R219: Chính quy
A220: 219 | B220: 2254078844 | C220: =VLOOKUP($B220,'DS nhan HPTN'!$B:$L,2,0) -> Nguyễn Thị Vy | D220: =VLOOKUP($B220,'DL DSDV PH'!B:F,5,0) -> 12/09/2004 | E220: =VLOOKUP(B220,Sheet4!D:I,5,0) -> 12/09/2004 | F220: =IF(D220=E220,"T","F") -> T | G220: =VLOOKUP(B220,Sheet4!D:I,6,0) -> 058304008638 | H220: =VLOOKUP($B220,Sheet4!$D:$M,8,0) -> Khánh Hoà | I220: =VLOOKUP($B220,Sheet4!$D:$M,9,0) -> Kinh | J220: =VLOOKUP($B220,'DS nhan HPTN'!$B:$L,3,0) -> S25-64LG1 | K220: =VLOOKUP($J220,'DL tạo lớp'!$B:$C,2,0) -> K64 | L220: 3.42 | M220: =VLOOKUP($B220,'DS nhan HPTN'!$B:$L,7,0) -> Thực trạng hoạt động giao nhận hàng hoá xuất khẩu nguyên container bằng đường biển tại Công ty Cổ phần Xuất Nhập Khẩu Logimex | N220: =VLOOKUP($B220,'DS nhan HPTN'!$B:$L,8,0) -> ThS. Trần Đức Thành | O220: ThS. Phạm Thị Duấn | P220: =VLOOKUP($B220,'DS nhan HPTN'!$B:$L,10,0) -> Logistics và quản lý chuỗi cung ứng | Q220: =VLOOKUP($B220,'DS nhan HPTN'!$B:$L,11,0) -> Kế toán & Quản trị kinh doanh | R220: Chính quy
...

Sheet Sheet9

Sheet Sheet4
A1: Dấu thời gian | B1: Địa chỉ email | C1: Họ và tên | D1: Mã số sinh viên | E1: Lớp | F1: Số điện thoại liên hệ | G1: mail liên hệ | H1: Ngày sinh | I1: CCCD | J1: Nơi sinh trước sát nhập (tỉnh) | K1: Nơi sinh sau sát nhập (tỉnh) | L1: Dân tộc | M1: Tôn Giáo | N1: Ảnh chụp CCCD
