Workbook

Sheet TH
A1: STT | B1: MSSV | C1: Họ và Tên | D1: Ngày sinh (Hậu kiểm) | E1: Ngày sinh (Phần mềm) | G1: Nơi sinh(Hậu kiểm) | H1: Nơi sinh (Phần mềm) | J1: Nơi sinh sau sát nhập | K1: Dân tộc (Hậu kiểm) | L1: Dân tộc (Phần mềm) | N1: Tôn giáo(Hậu kiểm) | O1: Tôn giáo(Phần mềm) | Q1: Lớp | R1: Ngành | S1: Khóa | T1: Hệ đào tạo | U1: Điểm TCTL | V1: Tên Đề Tài | W1: GV Hướng dẫn 1 | X1: GV Hướng dẫn 2 | Y1: Bộ môn | Z1: Sồ lần đạt giải
Z2: Cấp trường | AB2: Cấp bộ/quốc gia
Z3: Nghiên cứu khoa học | AA3: Olympic | AB3: Nghiên cứu khoa học | AC3: Olympic
A4: 1 | B4: 1954025484 | C4: Nguyễn Thị Ngọc Huyền | D4: =VLOOKUP(B4,Sheet3!$B:$I,3,0) -> #N/A | E4: =VLOOKUP($B4,Sheet4!$B:$L,4,0) -> 04/01/2001 | G4: =VLOOKUP($B4,Sheet3!$B:$I,5,0) -> #N/A | H4: =VLOOKUP($B4,Sheet4!$B:$L,5,0) -> Trường Tây, Hòa Thành, Tây Ninh | I4: =VLOOKUP(B4,[1]Sheet3!$D:$K,5,0) -> #N/A | K4: =VLOOKUP($B4,Sheet3!$B:$I,6,0) -> #N/A | L4: =VLOOKUP($B4,Sheet4!$B:$L,10,0) -> Kinh | N4: =VLOOKUP($B4,Sheet3!$B:$I,7,0) -> #N/A | O4: =VLOOKUP($B4,Sheet4!$B:$L,11,0) -> không | Q4: S22-61QT-TMĐT | R4: Quản trị kinh doanh thương mại điện tử | S4: K61 | T4: Chính quy | U4: 2.11 | V4: Hoàn thiện hoạt động bán hàng tại Công ty Cổ phần Đầu tư và Phát triển Bất động sản Richard Land | W4: ThS. Dương Quốc Minh Triều | Y4: Bộ môn Kế toán và Quản trị kinh doanh
A5: 2 | B5: 1954025583 | C5: Đỗ Ngọc Quỳnh Anh | D5: =VLOOKUP(B5,Sheet3!$B:$I,3,0) -> #N/A | E5: =VLOOKUP($B5,Sheet4!$B:$L,4,0) -> 17/07/2001 | F5: 17/07/2001 | G5: =VLOOKUP($B5,Sheet3!$B:$I,5,0) -> #N/A | H5: =VLOOKUP($B5,Sheet4!$B:$L,5,0) -> Thành phố Hồ Chí Minh | I5: Thành phố Hồ Chí Minh | J5: Thành phố Hồ Chí Minh | K5: =VLOOKUP($B5,Sheet3!$B:$I,6,0) -> #N/A | L5: =VLOOKUP($B5,Sheet4!$B:$L,10,0) -> Kinh | M5: Kinh | N5: =VLOOKUP($B5,Sheet3!$B:$I,7,0) -> #N/A | O5: =VLOOKUP($B5,Sheet4!$B:$L,11,0) -> Không có | Q5: S22-61QT-TMĐT | R5: Quản trị kinh doanh thương mại điện tử | S5: K61 | T5: Chính quy | U5: 1.93 | V5: Hoàn thiện công tác đào tạo nguồn nhân lực tại Công ty Trách Nhiệm Hữu Hạn Merimen Technologies (VIỆT NAM) | W5: ThS. Dương Quốc Minh Triều | Y5: Bộ môn Kế toán và Quản trị kinh doanh
A6: 3 | B6: 2154027096 | C6: Phạm Thị Thuý Hiền | D6: =VLOOKUP(B6,Sheet3!$B:$I,3,0) -> #N/A | E6: =VLOOKUP($B6,Sheet4!$B:$L,4,0) -> 19/12/2003 | F6: 19/12/2003 | G6: =VLOOKUP($B6,Sheet3!$B:$I,5,0) -> #N/A | H6: =VLOOKUP($B6,Sheet4!$B:$L,5,0) -> Tp.HCM | I6: Thành phố Hồ Chí Minh | J6: Thành phố Hồ Chí Minh | K6: =VLOOKUP($B6,Sheet3!$B:$I,6,0) -> #N/A | L6: =VLOOKUP($B6,Sheet4!$B:$L,10,0) -> Kinh | M6: Kinh | N6: =VLOOKUP($B6,Sheet3!$B:$I,7,0) -> #N/A | O6: =VLOOKUP($B6,Sheet4!$B:$L,11,0) -> 1263 | Q6: S24-63QT-Mar | R6: Quản trị Marketing | S6: K63 | T6: Chính quy | U6: 1.81 | V6: Hoàn thiện công tác chăm sóc khách hàng tại Công ty TNHH Vận Tải Dương Nguyên | W6: ThS. Dương Quốc Minh Triều | Y6: Bộ môn Kế toán và Quản trị kinh doanh
A7: 4 | B7: 2154027672 | C7: Đặng Thị Tâm Đoan | D7: =VLOOKUP(B7,Sheet3!$B:$I,3,0) -> #N/A | E7: =VLOOKUP($B7,Sheet4!$B:$L,4,0) -> 28/11/2003 | F7: 28/11/2003 | G7: =VLOOKUP($B7,Sheet3!$B:$I,5,0) -> #N/A | H7: =VLOOKUP($B7,Sheet4!$B:$L,5,0) -> Tây NInh | I7: =VLOOKUP(B7,[1]Sheet3!$D:$K,5,0) -> Tây Ninh | J7: Tây Ninh | K7: =VLOOKUP($B7,Sheet3!$B:$I,6,0) -> #N/A | L7: =VLOOKUP($B7,Sheet4!$B:$L,10,0) -> Kinh | M7: Kinh | N7: =VLOOKUP($B7,Sheet3!$B:$I,7,0) -> #N/A | O7: =VLOOKUP($B7,Sheet4!$B:$L,11,0) -> 173 | P7: Không | Q7: S24-63QT-Mar | R7: Quản trị Marketing | S7: K63 | T7: Chính quy | U7: 1.98 | V7: Hoàn thiện hoạt động chăm sóc khách hàng của Công ty TNHH Tiến Minh Quốc | W7: ThS. Dương Quốc Minh Triều | Y7: Bộ môn Kế toán và Quản trị kinh doanh
A8: 5 | B8: 2154027147 | C8: Nguyễn Thị Tiểu Yến | D8: =VLOOKUP(B8,Sheet3!$B:$I,3,0) -> #N/A | E8: =VLOOKUP($B8,Sheet4!$B:$L,4,0) -> 09/11/2003 | F8: 09/11/2003 | G8: =VLOOKUP($B8,Sheet3!$B:$I,5,0) -> #N/A | H8: =VLOOKUP($B8,Sheet4!$B:$L,5,0) -> Đồng Tháp | I8: =VLOOKUP(B8,[1]Sheet3!$D:$K,5,0) -> #N/A | J8: Đồng Tháp | K8: =VLOOKUP($B8,Sheet3!$B:$I,6,0) -> #N/A | L8: =VLOOKUP($B8,Sheet4!$B:$L,10,0) -> Kinh | M8: Kinh | N8: =VLOOKUP($B8,Sheet3!$B:$I,7,0) -> #N/A | O8: =VLOOKUP($B8,Sheet4!$B:$L,11,0) -> 1314 | Q8: S24-63QT-Mar | R8: Quản trị Marketing | S8: K63 | T8: Chính quy | U8: 2.13 | V8: Hoàn thiện hoạt động chăm sóc khách hàng cá nhân tại Ngân Hàng Thương Mại Cổ Phần Quân Đội Chi Nhánh Bắc Sài Gòn | W8: ThS. Dương Quốc Minh Triều | Y8: Bộ môn Kế toán và Quản trị kinh doanh
A9: 6 | B9: 2154027747 | C9: Nguyễn Thị Ánh Tuyết | D9: =VLOOKUP(B9,Sheet3!$B:$I,3,0) -> #N/A | E9: =VLOOKUP($B9,Sheet4!$B:$L,4,0) -> 05/05/2002 | F9: 05/05/2002 | G9: =VLOOKUP($B9,Sheet3!$B:$I,5,0) -> #N/A | H9: =VLOOKUP($B9,Sheet4!$B:$L,5,0) -> Đăk Lăk | I9: =VLOOKUP(B9,[1]Sheet3!$D:$K,5,0) -> Đắk lắk | J9: Đắk Lắk | K9: =VLOOKUP($B9,Sheet3!$B:$I,6,0) -> #N/A | L9: =VLOOKUP($B9,Sheet4!$B:$L,10,0) -> Kinh | M9: Kinh | N9: =VLOOKUP($B9,Sheet3!$B:$I,7,0) -> #N/A | O9: =VLOOKUP($B9,Sheet4!$B:$L,11,0) -> 248 | P9: Không | Q9: S24-63QT-Mar | R9: Quản trị Marketing | S9: K63 | T9: Chính quy | U9: 1.93 | V9: Hoàn thiện hoạt động chăm sóc khách hàng tại Công ty TNHH Lập Văn | W9: ThS. Nguyễn Thị Diễm Trang | Y9: Bộ môn Kế toán và Quản trị kinh doanh
A10: 7 | B10: 2154027088 | C10: Trịnh Thuý Duy | D10: =VLOOKUP(B10,Sheet3!$B:$I,3,0) -> #N/A | E10: =VLOOKUP($B10,Sheet4!$B:$L,4,0) -> 20/07/2003 | F10: 20/07/2003 | G10: =VLOOKUP($B10,Sheet3!$B:$I,5,0) -> #N/A | H10: =VLOOKUP($B10,Sheet4!$B:$L,5,0) -> Bạc Liêu | I10: =VLOOKUP(B10,[1]Sheet3!$D:$K,5,0) -> #N/A | J10: Bạc Liêu | K10: =VLOOKUP($B10,Sheet3!$B:$I,6,0) -> #N/A | L10: =VLOOKUP($B10,Sheet4!$B:$L,10,0) -> Kinh | M10: Kinh | N10: =VLOOKUP($B10,Sheet3!$B:$I,7,0) -> #N/A | O10: =VLOOKUP($B10,Sheet4!$B:$L,11,0) -> 1255 | Q10: S24-63QT-Mar | R10: Quản trị Marketing | S10: K63 | T10: Chính quy | U10: 1.96 | V10: Hoàn thiện hoạt động Marketing tại Công ty TNHH Nhựa Công-Nông nghiệp Văn Minh | W10: ThS. Nguyễn Thị Diễm Trang | Y10: Bộ môn Kế toán và Quản trị kinh doanh
A11: 8 | B11: 2154027319 | C11: Nguyễn Thị Kiều Diễm | D11: =VLOOKUP(B11,Sheet3!$B:$I,3,0) -> #N/A | E11: =VLOOKUP($B11,Sheet4!$B:$L,4,0) -> 09/09/2003 | F11: 09/09/2003 | G11: =VLOOKUP($B11,Sheet3!$B:$I,5,0) -> #N/A | H11: =VLOOKUP($B11,Sheet4!$B:$L,5,0) -> Tây Ninh | I11: =VLOOKUP(B11,[1]Sheet3!$D:$K,5,0) -> #N/A | J11: Tây Ninh | K11: =VLOOKUP($B11,Sheet3!$B:$I,6,0) -> #N/A | L11: =VLOOKUP($B11,Sheet4!$B:$L,10,0) -> Kinh | M11: Kinh | N11: =VLOOKUP($B11,Sheet3!$B:$I,7,0) -> #N/A | O11: =VLOOKUP($B11,Sheet4!$B:$L,11,0) -> 113 | Q11: S24-63QT-Mar | R11: Quản trị Marketing | S11: K63 | T11: Chính quy | U11: 2.18 | V11: Hoàn thiện hoạt động Marketing tại Công ty Cổ phần Dược Tâm Dược | W11: ThS. Nguyễn Thị Diễm Trang | Y11: Bộ môn Kế toán và Quản trị kinh doanh
A12: 9 | B12: 2154027273 | C12: Đỗ Kim Nhân | D12: =VLOOKUP(B12,Sheet3!$B:$I,3,0) -> #N/A | E12: =VLOOKUP($B12,Sheet4!$B:$L,4,0) -> 24/10/2003 | F12: 23/10/2003 | G12: =VLOOKUP($B12,Sheet3!$B:$I,5,0) -> #N/A | H12: =VLOOKUP($B12,Sheet4!$B:$L,5,0) -> Bạc Liêu | I12: =VLOOKUP(B12,[1]Sheet3!$D:$K,5,0) -> #N/A | J12: Cà Màu | K12: =VLOOKUP($B12,Sheet3!$B:$I,6,0) -> #N/A | L12: =VLOOKUP($B12,Sheet4!$B:$L,10,0) -> Kinh | M12: Kinh | N12: =VLOOKUP($B12,Sheet3!$B:$I,7,0) -> #N/A | O12: =VLOOKUP($B12,Sheet4!$B:$L,11,0) -> 1440 | Q12: S24-63QT-Mar | R12: Quản trị Marketing | S12: K63 | T12: Chính quy | U12: 2.3 | V12: Hoàn thiện hoạt động chăm sóc khách hàng tại Showroom Vinfast - D1 | W12: ThS. Nguyễn Thị Diễm Trang | Y12: Bộ môn Kế toán và Quản trị kinh doanh
A13: 10 | B13: 2154027730 | C13: Vũ Thị Thuý Nhi | D13: =VLOOKUP(B13,Sheet3!$B:$I,3,0) -> #N/A | E13: =VLOOKUP($B13,Sheet4!$B:$L,4,0) -> 01/11/2003 | F13: 01/11/2003 | G13: =VLOOKUP($B13,Sheet3!$B:$I,5,0) -> #N/A | H13: =VLOOKUP($B13,Sheet4!$B:$L,5,0) -> Đăk Lăk | I13: =VLOOKUP(B13,[1]Sheet3!$D:$K,5,0) -> #N/A | J13: Đắk Lắk | K13: =VLOOKUP($B13,Sheet3!$B:$I,6,0) -> #N/A | L13: =VLOOKUP($B13,Sheet4!$B:$L,10,0) -> Kinh | M13: Kinh | N13: =VLOOKUP($B13,Sheet3!$B:$I,7,0) -> #N/A | O13: =VLOOKUP($B13,Sheet4!$B:$L,11,0) -> 231 | Q13: S24-63QT-Mar | R13: Quản trị Marketing | S13: K63 | T13: Chính quy | U13: 2.43 | V13: Hoàn thiện hoạt động marketing tại công ty đào tạo Dược Alophar. | W13: ThS. Nguyễn Thị Diễm Trang | Y13: Bộ môn Kế toán và Quản trị kinh doanh
A14: 11 | B14: 1954025556 | C14: Phạm Đàm Mỹ Duyên | D14: =VLOOKUP(B14,Sheet3!$B:$I,3,0) -> #N/A | E14: =VLOOKUP($B14,Sheet4!$B:$L,4,0) -> 13/07/2001 | F14: 13/07/2001 | G14: =VLOOKUP($B14,Sheet3!$B:$I,5,0) -> #N/A | H14: =VLOOKUP($B14,Sheet4!$B:$L,5,0) -> Thôn Phong Niên, Xã Hòa Thắng , Huyện Phú Hòa , Tỉnh Phú Yên | I14: =VLOOKUP(B14,[1]Sheet3!$D:$K,5,0) -> #N/A | J14: Đắk Lắk | K14: =VLOOKUP($B14,Sheet3!$B:$I,6,0) -> #N/A | L14: =VLOOKUP($B14,Sheet4!$B:$L,10,0) -> Kinh | M14: Kinh | N14: =VLOOKUP($B14,Sheet3!$B:$I,7,0) -> #N/A | O14: =VLOOKUP($B14,Sheet4!$B:$L,11,0) -> Không | Q14: S22-61QT-Mar | R14: Quản trị Marketing | S14: K61 | T14: Chính quy | U14: 1.91 | V14: Một số giải pháp hoàn thiện công tác tuyển dụng nhân sự tại Công ty Trách nhiệm hữu hạn Awards Shipping Agency Korea - Việt Nam | W14: ThS. Đỗ Duy Khương | Y14: Bộ môn Kế toán và Quản trị kinh doanh
A15: 12 | B15: 2054027653 | C15: Trần Thị Hải Yến | D15: =VLOOKUP(B15,Sheet3!$B:$I,3,0) -> 26/03/2002 | E15: =VLOOKUP($B15,Sheet4!$B:$L,4,0) -> 26/03/2002 | F15: 26/03/2002 | G15: =VLOOKUP($B15,Sheet3!$B:$I,5,0) -> 0 | H15: =VLOOKUP($B15,Sheet4!$B:$L,5,0) -> Lâm Đồng | I15: =VLOOKUP(B15,[1]Sheet3!$D:$K,5,0) -> #N/A | J15: Lâm Đồng | K15: =VLOOKUP($B15,Sheet3!$B:$I,6,0) -> 0 | L15: =VLOOKUP($B15,Sheet4!$B:$L,10,0) -> Kinh | M15: Kinh | N15: =VLOOKUP($B15,Sheet3!$B:$I,7,0) -> 0 | O15: =VLOOKUP($B15,Sheet4!$B:$L,11,0) -> 204 | Q15: S23-62QT-Mar | R15: Quản trị Marketing | S15: K62 | T15: Chính quy | U15: 2.11 | V15: Hoàn thiện hoạt động Digital Marketing tại Công ty Cổ phần Đầu tư và Phát triển Top Smiles | W15: ThS. Đỗ Duy Khương | Y15: Bộ môn Kế toán và Quản trị kinh doanh
A16: 13 | B16: 2054027441 | C16: Trần Lê Thanh Vy | D16: =VLOOKUP(B16,Sheet3!$B:$I,3,0) -> 24/04/2002 | E16: =VLOOKUP($B16,Sheet4!$B:$L,4,0) -> 24/04/2002 | F16: 24/04/2002 | G16: =VLOOKUP($B16,Sheet3!$B:$I,5,0) -> 0 | H16: =VLOOKUP($B16,Sheet4!$B:$L,5,0) -> Tp.Hồ Chí Minh | I16: =VLOOKUP(B16,[1]Sheet3!$D:$K,5,0) -> #N/A | J16: Thành phố Hồ Chí Minh | K16: =VLOOKUP($B16,Sheet3!$B:$I,6,0) -> 0 | L16: =VLOOKUP($B16,Sheet4!$B:$L,10,0) -> Kinh | M16: Kinh | N16: =VLOOKUP($B16,Sheet3!$B:$I,7,0) -> 0 | O16: =VLOOKUP($B16,Sheet4!$B:$L,11,0) -> 0 | Q16: S24-62QT-KDQT | R16: Quản trị kinh doanh quốc tế | S16: K62 | T16: Chính quy | U16: 1.79 | V16: Hoàn thiện công tác đào tạo nhân lực tại Ngân Hàng TMCP Quốc Dân - Chi nhánh Sài Gòn – Phòng giao dịch Lê Hồng Phong | W16: ThS. Đỗ Duy Khương | Y16: Bộ môn Kế toán và Quản trị kinh doanh
A17: 14 | B17: 2154027685 | C17: Vũ Văn Tú | D17: =VLOOKUP(B17,Sheet3!$B:$I,3,0) -> #N/A | E17: =VLOOKUP($B17,Sheet4!$B:$L,4,0) -> 15/09/2003 | F17: 15/09/2003 | G17: =VLOOKUP($B17,Sheet3!$B:$I,5,0) -> #N/A | H17: =VLOOKUP($B17,Sheet4!$B:$L,5,0) -> Đồng Nai | I17: =VLOOKUP(B17,[1]Sheet3!$D:$K,5,0) -> #N/A | J17: Đồng Nai | K17: =VLOOKUP($B17,Sheet3!$B:$I,6,0) -> #N/A | L17: =VLOOKUP($B17,Sheet4!$B:$L,10,0) -> Kinh | M17: Kinh | N17: =VLOOKUP($B17,Sheet3!$B:$I,7,0) -> #N/A | O17: =VLOOKUP($B17,Sheet4!$B:$L,11,0) -> 186 | Q17: S24-63QT-Mar | R17: Quản trị Marketing | S17: K63 | T17: Chính quy | U17: 2.09 | V17: Giải pháp hoàn thiện hoạt động Marketing mix tại Công ty Trách nhiệm hữu hạn Trung tâm Thể dục Thể hình và Yoga Victoria | W17: ThS. Đỗ Duy Khương | Y17: Bộ môn Kế toán và Quản trị kinh doanh
A18: 15 | B18: 2154027287 | C18: Trần Thị Thu Thương | D18: =VLOOKUP(B18,Sheet3!$B:$I,3,0) -> #N/A | E18: =VLOOKUP($B18,Sheet4!$B:$L,4,0) -> 30/01/2003 | F18: 30/01/2003 | G18: =VLOOKUP($B18,Sheet3!$B:$I,5,0) -> #N/A | H18: =VLOOKUP($B18,Sheet4!$B:$L,5,0) -> Quảng Nam | I18: =VLOOKUP(B18,[1]Sheet3!$D:$K,5,0) -> #N/A | J18: Đà Nẵng | K18: =VLOOKUP($B18,Sheet3!$B:$I,6,0) -> #N/A | L18: =VLOOKUP($B18,Sheet4!$B:$L,10,0) -> Kinh | M18: Kinh | N18: =VLOOKUP($B18,Sheet3!$B:$I,7,0) -> #N/A | O18: =VLOOKUP($B18,Sheet4!$B:$L,11,0) -> 1454 | Q18: S24-63QT-Mar | R18: Quản trị Marketing | S18: K63 | T18: Chính quy | U18: 2.31 | V18: Một số giải pháp hoàn thiện hoạt động môi giới chứng khoán tại Công ty Cổ phần Chứng khoán VPS – Chi nhánh Thành phố Hồ Chí Minh | W18: ThS. Đỗ Duy Khương | Y18: Bộ môn Kế toán và Quản trị kinh doanh
A19: 16 | B19: 2154027278 | C19: Cao Hỷ Phong | D19: =VLOOKUP(B19,Sheet3!$B:$I,3,0) -> #N/A | E19: =VLOOKUP($B19,Sheet4!$B:$L,4,0) -> 27/05/2003 | F19: 27/05/2003 | G19: =VLOOKUP($B19,Sheet3!$B:$I,5,0) -> #N/A | H19: =VLOOKUP($B19,Sheet4!$B:$L,5,0) -> BV HÙng Vương, Tp.HCM | I19: =VLOOKUP(B19,[1]Sheet3!$D:$K,5,0) -> Thành phố Hồ Chí Minh | J19: Thành phố Hồ Chí Minh | K19: =VLOOKUP($B19,Sheet3!$B:$I,6,0) -> #N/A | L19: =VLOOKUP($B19,Sheet4!$B:$L,10,0) -> Hoa | M19: Hoa | N19: =VLOOKUP($B19,Sheet3!$B:$I,7,0) -> #N/A | O19: =VLOOKUP($B19,Sheet4!$B:$L,11,0) -> 1445 | P19: Không | Q19: S24-63QT-KDQT | R19: Quản trị kinh doanh quốc tế | S19: K63 | T19: Chính quy | U19: 2.59 | V19: Hoàn thiện hoạt động công tác bán hàng tại Công ty TNHH Thương mại Quốc Tế Vĩnh Hòa Thịnh | W19: TS. Hà Kiên Tân | Y19: Bộ môn Kế toán và Quản trị kinh doanh
A20: 17 | B20: 2154027271 | C20: Huỳnh Thị Thanh Nghi | D20: =VLOOKUP(B20,Sheet3!$B:$I,3,0) -> #N/A | E20: =VLOOKUP($B20,Sheet4!$B:$L,4,0) -> 11/06/2003 | F20: 11/06/2003 | G20: =VLOOKUP($B20,Sheet3!$B:$I,5,0) -> #N/A | H20: =VLOOKUP($B20,Sheet4!$B:$L,5,0) -> Phú Yên | I20: =VLOOKUP(B20,[1]Sheet3!$D:$K,5,0) -> Khu phố 1 phường Phú Thạnh TP Tuy Hòa tỉnh Phú Yên | J20: Đắk Lắk | K20: =VLOOKUP($B20,Sheet3!$B:$I,6,0) -> #N/A | L20: =VLOOKUP($B20,Sheet4!$B:$L,10,0) -> Kinh | M20: Kinh | N20: =VLOOKUP($B20,Sheet3!$B:$I,7,0) -> #N/A | O20: =VLOOKUP($B20,Sheet4!$B:$L,11,0) -> 1438 | P20: Không | Q20: S24-63QT-KDQT | R20: Quản trị kinh doanh quốc tế | S20: K63 | T20: Chính quy | U20: 2.27 | V20: Hoàn thiện hoạt động truyền thông số tại Công ty cổ phần Bất động sản Thế Kỷ chi nhánh TP Hồ Chí Minh | W20: TS. Hà Kiên Tân | Y20: Bộ môn Kế toán và Quản trị kinh doanh
A21: 18 | B21: 2154027689 | C21: Đỗ Ngọc Linh | D21: =VLOOKUP(B21,Sheet3!$B:$I,3,0) -> #N/A | E21: =VLOOKUP($B21,Sheet4!$B:$L,4,0) -> 12/01/2003 | F21: 12/01/2003 | G21: =VLOOKUP($B21,Sheet3!$B:$I,5,0) -> #N/A | H21: =VLOOKUP($B21,Sheet4!$B:$L,5,0) -> Quảng Nam | I21: =VLOOKUP(B21,[1]Sheet3!$D:$K,5,0) -> #N/A | J21: Quảng Nam | K21: =VLOOKUP($B21,Sheet3!$B:$I,6,0) -> #N/A | L21: =VLOOKUP($B21,Sheet4!$B:$L,10,0) -> Kinh | M21: Kinh | N21: =VLOOKUP($B21,Sheet3!$B:$I,7,0) -> #N/A | O21: =VLOOKUP($B21,Sheet4!$B:$L,11,0) -> 190 | Q21: S24-63QT-Mar | R21: Quản trị Marketing | S21: K63 | T21: Chính quy | U21: 2.41 | V21: Hoàn thiện công tác đào tạo nguồn nhân lực tại Công ty Cổ phần Central Retail Corporation (Việt Nam) | W21: TS. Trần Thị Thanh Huyền | Y21: Bộ môn Kế toán và Quản trị kinh doanh
A22: 19 | B22: 2154027653 | C22: Vương Hà Châu | D22: =VLOOKUP(B22,Sheet3!$B:$I,3,0) -> #N/A | E22: =VLOOKUP($B22,Sheet4!$B:$L,4,0) -> 23/09/2003 | F22: 23/09/2003 | G22: =VLOOKUP($B22,Sheet3!$B:$I,5,0) -> #N/A | H22: =VLOOKUP($B22,Sheet4!$B:$L,5,0) -> Hà Tây | I22: =VLOOKUP(B22,[1]Sheet3!$D:$K,5,0) -> Tp Hà Nội | J22: Hà Nội | K22: =VLOOKUP($B22,Sheet3!$B:$I,6,0) -> #N/A | L22: =VLOOKUP($B22,Sheet4!$B:$L,10,0) -> Kinh | M22: Kinh | N22: =VLOOKUP($B22,Sheet3!$B:$I,7,0) -> #N/A | O22: =VLOOKUP($B22,Sheet4!$B:$L,11,0) -> 154 | P22: Không | Q22: S24-63QT-Mar | R22: Quản trị Marketing | S22: K63 | T22: Chính quy | U22: 2.49 | V22: Nâng cao chất lượng dịch vụ ngân hàng số tại ngân hàng TMCP Quân Đội chi nhánh Bắc Sài Gòn | W22: TS. Hà Kiên Tân | Y22: Bộ môn Kế toán và Quản trị kinh doanh
A23: 20 | B23: 2154027279 | C23: Lê Hoàng Phong | D23: =VLOOKUP(B23,Sheet3!$B:$I,3,0) -> #N/A | E23: =VLOOKUP($B23,Sheet4!$B:$L,4,0) -> 22/02/2003 | F23: 22/02/2003 | G23: =VLOOKUP($B23,Sheet3!$B:$I,5,0) -> #N/A | H23: =VLOOKUP($B23,Sheet4!$B:$L,5,0) -> BRVT | I23: =VLOOKUP(B23,[1]Sheet3!$D:$K,5,0) -> BÀ RỊA - VŨNG TÀU | J23: Thành phố Hồ Chí Minh | K23: =VLOOKUP($B23,Sheet3!$B:$I,6,0) -> #N/A | L23: =VLOOKUP($B23,Sheet4!$B:$L,10,0) -> 1446 | M23: Kinh | N23: =VLOOKUP($B23,Sheet3!$B:$I,7,0) -> #N/A | O23: =VLOOKUP($B23,Sheet4!$B:$L,11,0) -> 1446 | P23: Không | Q23: S24-63QT-Mar | R23: Quản trị Marketing | S23: K63 | T23: Chính quy | U23: 2.07 | V23: Hoàn thiện hoạt động chăm sóc khách hàng tại Công ty TNHH Thương mại KATA chi nhánh TP Hồ Chí Minh | W23: TS. Hà Kiên Tân | Y23: Bộ môn Kế toán và Quản trị kinh doanh
A24: 21 | B24: 2154077316 | C24: Trương Khả Vy | D24: =VLOOKUP(B24,Sheet3!$B:$I,3,0) -> #N/A | E24: =VLOOKUP($B24,Sheet4!$B:$L,4,0) -> 30/06/2003 | F24: 30/06/2003 | G24: =VLOOKUP($B24,Sheet3!$B:$I,5,0) -> #N/A | H24: =VLOOKUP($B24,Sheet4!$B:$L,5,0) -> Tỉnh Bình Định | I24: =VLOOKUP(B24,[1]Sheet3!$D:$K,5,0) -> Bệnh viện an nhơn | J24: Gia Lai | K24: =VLOOKUP($B24,Sheet3!$B:$I,6,0) -> #N/A | L24: =VLOOKUP($B24,Sheet4!$B:$L,10,0) -> Kinh | M24: Kinh | N24: =VLOOKUP($B24,Sheet3!$B:$I,7,0) -> #N/A | O24: =VLOOKUP($B24,Sheet4!$B:$L,11,0) -> Không | P24: Không | Q24: S24-63QT-Mar | R24: Quản trị Marketing | S24: K63 | T24: Chính quy | U24: 2.08 | V24: Nâng cao chất lượng dịch vụ khách hàng cá nhân tại ngân hàng Việt Nam Thịnh Vượng chi nhánh Quang Trung | W24: TS. Hà Kiên Tân | Y24: Bộ môn Kế toán và Quản trị kinh doanh
A25: 22 | B25: 2154027094 | C25: Đặng Thanh Hiền | D25: =VLOOKUP(B25,Sheet3!$B:$I,3,0) -> #N/A | E25: =VLOOKUP($B25,Sheet4!$B:$L,4,0) -> 11/06/2003 | F25: 11/06/2003 | G25: =VLOOKUP($B25,Sheet3!$B:$I,5,0) -> #N/A | H25: =VLOOKUP($B25,Sheet4!$B:$L,5,0) -> Tp.HCM | I25: =VLOOKUP(B25,[1]Sheet3!$D:$K,5,0) -> #N/A | J25: Thành phố Hồ Chí Minh | K25: =VLOOKUP($B25,Sheet3!$B:$I,6,0) -> #N/A | L25: =VLOOKUP($B25,Sheet4!$B:$L,10,0) -> Kinh | M25: Kinh | N25: =VLOOKUP($B25,Sheet3!$B:$I,7,0) -> #N/A | O25: =VLOOKUP($B25,Sheet4!$B:$L,11,0) -> 1261 | Q25: S24-63QT-Mar | R25: Quản trị Marketing | S25: K63 | T25: Chính quy | U25: 1.97 | V25: Hoàn thiện hoạt động công tác bán hàng tại Công ty cổ phần Đầu tư Goldwings | W25: TS. Hà Kiên Tân | Y25: Bộ môn Kế toán và Quản trị kinh doanh
A26: 23 | B26: 2154027262 | C26: Nguyễn Thị Lan | D26: =VLOOKUP(B26,Sheet3!$B:$I,3,0) -> #N/A | E26: =VLOOKUP($B26,Sheet4!$B:$L,4,0) -> 04/04/2002 | F26: 04/04/2002 | G26: =VLOOKUP($B26,Sheet3!$B:$I,5,0) -> #N/A | H26: =VLOOKUP($B26,Sheet4!$B:$L,5,0) -> 0 | I26: =VLOOKUP(B26,[1]Sheet3!$D:$K,5,0) -> Bắc Giang | J26: Bắc Ninh | K26: =VLOOKUP($B26,Sheet3!$B:$I,6,0) -> #N/A | L26: =VLOOKUP($B26,Sheet4!$B:$L,10,0) -> 1429 | M26: Kinh | N26: =VLOOKUP($B26,Sheet3!$B:$I,7,0) -> #N/A | O26: =VLOOKUP($B26,Sheet4!$B:$L,11,0) -> 1429 | P26: Không | Q26: S24-63QT-Mar | R26: Quản trị Marketing | S26: K63 | T26: Chính quy | U26: 2.26 | V26: Nâng cao hiệu quả hoạt động truyền thông trên mạng xã hội tại Công ty TNHH Trung Tâm Thể Dục Thể Hình & Yoga Victoria | W26: ThS. Tăng Thị Lưu | Y26: Bộ môn Kế toán và Quản trị kinh doanh
A27: 24 | B27: 2154027656 | C27: Trương Thị Phương Thảo | D27: =VLOOKUP(B27,Sheet3!$B:$I,3,0) -> #N/A | E27: =VLOOKUP($B27,Sheet4!$B:$L,4,0) -> 16/05/2003 | F27: 16/05/2003 | G27: =VLOOKUP($B27,Sheet3!$B:$I,5,0) -> #N/A | H27: =VLOOKUP($B27,Sheet4!$B:$L,5,0) -> Kiên Giang | I27: =VLOOKUP(B27,[1]Sheet3!$D:$K,5,0) -> #N/A | J27: An Giang | K27: =VLOOKUP($B27,Sheet3!$B:$I,6,0) -> #N/A | L27: =VLOOKUP($B27,Sheet4!$B:$L,10,0) -> 157 | M27: Kinh | N27: =VLOOKUP($B27,Sheet3!$B:$I,7,0) -> #N/A | O27: =VLOOKUP($B27,Sheet4!$B:$L,11,0) -> 157 | Q27: S24-63QT-Mar | R27: Quản trị Marketing | S27: K63 | T27: Chính quy | U27: 2.44 | V27: Nâng cao hiệu quả hoạt động bán hàng tại Công ty TNHH Khang Quân Home Việt Nam | W27: ThS. Tăng Thị Lưu | Y27: Bộ môn Kế toán và Quản trị kinh doanh
A28: 25 | B28: 2154027133 | C28: Nguyễn Thị Bích Trà | D28: =VLOOKUP(B28,Sheet3!$B:$I,3,0) -> #N/A | E28: =VLOOKUP($B28,Sheet4!$B:$L,4,0) -> 28/02/2003 | F28: 28/02/2003 | G28: =VLOOKUP($B28,Sheet3!$B:$I,5,0) -> #N/A | H28: =VLOOKUP($B28,Sheet4!$B:$L,5,0) -> Quảng Ngãi | I28: =VLOOKUP(B28,[1]Sheet3!$D:$K,5,0) -> #N/A | J28: Đắk Lắk | K28: =VLOOKUP($B28,Sheet3!$B:$I,6,0) -> #N/A | L28: =VLOOKUP($B28,Sheet4!$B:$L,10,0) -> Kinh | M28: Kinh | N28: =VLOOKUP($B28,Sheet3!$B:$I,7,0) -> #N/A | O28: =VLOOKUP($B28,Sheet4!$B:$L,11,0) -> 1300 | Q28: S24-63QT-Mar | R28: Quản trị Marketing | S28: K63 | T28: Chính quy | U28: 1.76 | V28: Giải pháp nâng cao hiệu quả hoạt động chăm sóc khách hàng tại Công ty Xuất Nhập Khẩu Thuốc Lá | W28: ThS. Tăng Thị Lưu | Y28: Bộ môn Kế toán và Quản trị kinh doanh
A29: 26 | B29: 2154027650 | C29: Lê Võ Giáng My | D29: =VLOOKUP(B29,Sheet3!$B:$I,3,0) -> #N/A | E29: =VLOOKUP($B29,Sheet4!$B:$L,4,0) -> 25/03/2003 | F29: 25/03/2003 | G29: =VLOOKUP($B29,Sheet3!$B:$I,5,0) -> #N/A | H29: =VLOOKUP($B29,Sheet4!$B:$L,5,0) -> BV NDGia Định, Tp.HCM | I29: =VLOOKUP(B29,[1]Sheet3!$D:$K,5,0) -> #N/A | J29: Thành phố Hồ Chí Minh | K29: =VLOOKUP($B29,Sheet3!$B:$I,6,0) -> #N/A | L29: =VLOOKUP($B29,Sheet4!$B:$L,10,0) -> 151 | M29: Kinh | N29: =VLOOKUP($B29,Sheet3!$B:$I,7,0) -> #N/A | O29: =VLOOKUP($B29,Sheet4!$B:$L,11,0) -> 151 | Q29: S24-63QT-Mar | R29: Quản trị Marketing | S29: K63 | T29: Chính quy | U29: 2.78 | V29: Xây dựng kế hoạch Digital Marketing cho Công ty TNHH MTV Hoàng Long Garden | W29: ThS. Tăng Thị Lưu | Y29: Bộ môn Kế toán và Quản trị kinh doanh
A30: 27 | B30: 2154027736 | C30: Trương Thị Hương Giang | D30: =VLOOKUP(B30,Sheet3!$B:$I,3,0) -> #N/A | E30: =VLOOKUP($B30,Sheet4!$B:$L,4,0) -> 20/05/2003 | F30: 20/05/2003 | G30: =VLOOKUP($B30,Sheet3!$B:$I,5,0) -> #N/A | H30: =VLOOKUP($B30,Sheet4!$B:$L,5,0) -> Đăk Lăk | I30: =VLOOKUP(B30,[1]Sheet3!$D:$K,5,0) -> #N/A | J30: Đắk Lắk | K30: =VLOOKUP($B30,Sheet3!$B:$I,6,0) -> #N/A | L30: =VLOOKUP($B30,Sheet4!$B:$L,10,0) -> Kinh | M30: Kinh | N30: =VLOOKUP($B30,Sheet3!$B:$I,7,0) -> #N/A | O30: =VLOOKUP($B30,Sheet4!$B:$L,11,0) -> 237 | Q30: S24-63QT-Mar | R30: Quản trị Marketing | S30: K63 | T30: Chính quy | U30: 2.04 | V30: Nâng cao hiệu quả hoạt động Marketing Online tại Công ty Địa Ốc Trường Thọ | W30: ThS. Tăng Thị Lưu | Y30: Bộ môn Kế toán và Quản trị kinh doanh
A31: 28 | B31: 2154027125 | C31: Bùi Trường Sơn | D31: =VLOOKUP(B31,Sheet3!$B:$I,3,0) -> #N/A | E31: =VLOOKUP($B31,Sheet4!$B:$L,4,0) -> 11/05/2003 | F31: 11/05/2003 | G31: =VLOOKUP($B31,Sheet3!$B:$I,5,0) -> #N/A | H31: =VLOOKUP($B31,Sheet4!$B:$L,5,0) -> Hải Phòng | I31: =VLOOKUP(B31,[1]Sheet3!$D:$K,5,0) -> #N/A | J31: Hải Phòng | K31: =VLOOKUP($B31,Sheet3!$B:$I,6,0) -> #N/A | L31: =VLOOKUP($B31,Sheet4!$B:$L,10,0) -> Kinh | M31: Kinh | N31: =VLOOKUP($B31,Sheet3!$B:$I,7,0) -> #N/A | O31: =VLOOKUP($B31,Sheet4!$B:$L,11,0) -> 1292 | Q31: S24-63QT-Mar | R31: Quản trị Marketing | S31: K63 | T31: Chính quy | U31: 2.17 | V31: Giải pháp nâng cao hiệu quả hoạt động truyền thông cho Công ty TNHH TVTK Xây dựng và PCCC Hải An | W31: ThS. Tăng Thị Lưu | Y31: Bộ môn Kế toán và Quản trị kinh doanh
A32: 29 | B32: 2154027904 | C32: Kiều Thị Kim Anh | D32: =VLOOKUP(B32,Sheet3!$B:$I,3,0) -> #N/A | E32: =VLOOKUP($B32,Sheet4!$B:$L,4,0) -> 17/11/2003 | F32: 17/11/2003 | G32: =VLOOKUP($B32,Sheet3!$B:$I,5,0) -> #N/A | H32: =VLOOKUP($B32,Sheet4!$B:$L,5,0) -> Tp.HCM | I32: =VLOOKUP(B32,[1]Sheet3!$D:$K,5,0) -> #N/A | J32: Thành phố Hồ Chí Minh | K32: =VLOOKUP($B32,Sheet3!$B:$I,6,0) -> #N/A | L32: =VLOOKUP($B32,Sheet4!$B:$L,10,0) -> Kinh | M32: Kinh | N32: =VLOOKUP($B32,Sheet3!$B:$I,7,0) -> #N/A | O32: =VLOOKUP($B32,Sheet4!$B:$L,11,0) -> 51 | Q32: S24-63QT-Mar | R32: Quản trị Marketing | S32: K63 | T32: Chính quy | U32: 1.89 | V32: Giải pháp Tối ưu hóa Kênh Phân phối nhằm Nâng cao Hiệu suất Bán hàng tại Công ty TNHH Pulmuone Việt Nam | W32: ThS. Tăng Thị Lưu | Y32: Bộ môn Kế toán và Quản trị kinh doanh
A33: 30 | B33: 2054027428 | C33: Nguyễn Ngọc Xuân Trang | D33: =VLOOKUP(B33,Sheet3!$B:$I,3,0) -> 29/10/2002 | E33: =VLOOKUP($B33,Sheet4!$B:$L,4,0) -> 29/10/2002 | F33: 29/10/2002 | G33: =VLOOKUP($B33,Sheet3!$B:$I,5,0) -> 0 | H33: =VLOOKUP($B33,Sheet4!$B:$L,5,0) -> An Giang | I33: =VLOOKUP(B33,[1]Sheet3!$D:$K,5,0) -> #N/A | J33: An Giang | K33: =VLOOKUP($B33,Sheet3!$B:$I,6,0) -> 0 | L33: =VLOOKUP($B33,Sheet4!$B:$L,10,0) -> Kinh | M33: Kinh | N33: =VLOOKUP($B33,Sheet3!$B:$I,7,0) -> 0 | O33: =VLOOKUP($B33,Sheet4!$B:$L,11,0) -> không | Q33: S24-62QT-Mar | R33: Quản trị Marketing | S33: K62 | T33: Chính quy | U33: 2.24 | V33: Thực trạng hoạt động marketing mix tại Công ty TNHH Tư vấn và Giáo dục Thiên Bảo | W33: TS. Trần Thị Thanh Huyền | Y33: Bộ môn Kế toán và Quản trị kinh doanh
A34: 31 | B34: 2154027723 | C34: Phạm Minh Quang | D34: =VLOOKUP(B34,Sheet3!$B:$I,3,0) -> #N/A | E34: =VLOOKUP($B34,Sheet4!$B:$L,4,0) -> 01/09/2003 | G34: =VLOOKUP($B34,Sheet3!$B:$I,5,0) -> #N/A | H34: =VLOOKUP($B34,Sheet4!$B:$L,5,0) -> Đăk Lăk | I34: =VLOOKUP(B34,[1]Sheet3!$D:$K,5,0) -> #N/A | K34: =VLOOKUP($B34,Sheet3!$B:$I,6,0) -> #N/A | L34: =VLOOKUP($B34,Sheet4!$B:$L,10,0) -> Kinh | N34: =VLOOKUP($B34,Sheet3!$B:$I,7,0) -> #N/A | O34: =VLOOKUP($B34,Sheet4!$B:$L,11,0) -> 224 | Q34: S24-63QT-KDQT | R34: Quản trị kinh doanh quốc tế | S34: K63 | T34: Chính quy | U34: 2.2 | V34: Hoàn thiện công tác chăm sóc khách hàng tại Công ty cổ phần CAD GROUP | W34: TS. Trần Thị Thanh Huyền | Y34: Bộ môn Kế toán và Quản trị kinh doanh
A35: 32 | B35: 2054027342 | C35: Phạm Cao Hiển | D35: =VLOOKUP(B35,Sheet3!$B:$I,3,0) -> 26/02/2002 | E35: =VLOOKUP($B35,Sheet4!$B:$L,4,0) -> 26/02/2001 | F35: 26/02/2001 | G35: =VLOOKUP($B35,Sheet3!$B:$I,5,0) -> 0 | H35: =VLOOKUP($B35,Sheet4!$B:$L,5,0) -> 0 | I35: =VLOOKUP(B35,[1]Sheet3!$D:$K,5,0) -> #N/A | J35: Thành phố Hồ Chí Minh | K35: =VLOOKUP($B35,Sheet3!$B:$I,6,0) -> 0 | L35: =VLOOKUP($B35,Sheet4!$B:$L,10,0) -> 0 | M35: Kinh | N35: =VLOOKUP($B35,Sheet3!$B:$I,7,0) -> 0 | O35: =VLOOKUP($B35,Sheet4!$B:$L,11,0) -> 0 | Q35: S24-63QT-KDQT | R35: Quản trị kinh doanh quốc tế | S35: K63 | T35: Chính quy | U35: 1.96 | V35: Hoàn thiện công tác chăm sóc khách hàng tại Công ty cổ phần Cashion | W35: TS. Trần Thị Thanh Huyền | Y35: Bộ môn Kế toán và Quản trị kinh doanh
A36: 33 | B36: 2154027661 | C36: Bùi Thị Phương Dung | D36: =VLOOKUP(B36,Sheet3!$B:$I,3,0) -> #N/A | E36: =VLOOKUP($B36,Sheet4!$B:$L,4,0) -> 02/06/2003 | F36: 02/06/2003 | G36: =VLOOKUP($B36,Sheet3!$B:$I,5,0) -> #N/A | H36: =VLOOKUP($B36,Sheet4!$B:$L,5,0) -> Thành phố Hồ Chí Minh | I36: =VLOOKUP(B36,[1]Sheet3!$D:$K,5,0) -> #N/A | J36: Thành phố Hồ Chí Minh | K36: =VLOOKUP($B36,Sheet3!$B:$I,6,0) -> #N/A | L36: =VLOOKUP($B36,Sheet4!$B:$L,10,0) -> Kinh | M36: Kinh | N36: =VLOOKUP($B36,Sheet3!$B:$I,7,0) -> #N/A | O36: =VLOOKUP($B36,Sheet4!$B:$L,11,0) -> Không | Q36: S24-63QT-KDQT | R36: Quản trị kinh doanh quốc tế | S36: K63 | T36: Chính quy | U36: 2.1 | V36: Hoạt động tuyển dụng tại Công ty TNHH Một Thành Viên TMDV Quốc Dũng: Thực trạng và giải pháp | W36: TS. Trần Thị Thanh Huyền | Y36: Bộ môn Kế toán và Quản trị kinh doanh
A37: 34 | B37: 2154025165 | C37: Nguyễn Khánh Vân | D37: =VLOOKUP(B37,Sheet3!$B:$I,3,0) -> #N/A | E37: =VLOOKUP($B37,Sheet4!$B:$L,4,0) -> 01/09/2003 | F37: 01/09/2003 | G37: =VLOOKUP($B37,Sheet3!$B:$I,5,0) -> #N/A | H37: =VLOOKUP($B37,Sheet4!$B:$L,5,0) -> Xã Vân Từ, huyện Phú Xuyên, thành phố Hà Nội | I37: =VLOOKUP(B37,[1]Sheet3!$D:$K,5,0) -> #N/A | J37: Hà Nội | K37: =VLOOKUP($B37,Sheet3!$B:$I,6,0) -> #N/A | L37: =VLOOKUP($B37,Sheet4!$B:$L,10,0) -> Kinh | M37: Kinh | N37: =VLOOKUP($B37,Sheet3!$B:$I,7,0) -> #N/A | O37: =VLOOKUP($B37,Sheet4!$B:$L,11,0) -> Không | Q37: S24-63QT-KDQT | R37: Quản trị kinh doanh quốc tế | S37: K63 | T37: Chính quy | U37: 2.48 | V37: Hoàn thiện công tác chăm sóc khách hàng tại Radisson Blu Resort Phú Quốc | W37: TS. Trần Thị Thanh Huyền | Y37: Bộ môn Kế toán và Quản trị kinh doanh
A38: 35 | B38: 2154027263 | C38: Nguyễn Thị Kiều Liên | D38: =VLOOKUP(B38,Sheet3!$B:$I,3,0) -> #N/A | E38: =VLOOKUP($B38,Sheet4!$B:$L,4,0) -> 20/12/2003 | F38: 20/12/2003 | G38: =VLOOKUP($B38,Sheet3!$B:$I,5,0) -> #N/A | H38: =VLOOKUP($B38,Sheet4!$B:$L,5,0) -> Phú Yên | I38: =VLOOKUP(B38,[1]Sheet3!$D:$K,5,0) -> Phú Yên | J38: Đắk Lắk | K38: =VLOOKUP($B38,Sheet3!$B:$I,6,0) -> #N/A | L38: =VLOOKUP($B38,Sheet4!$B:$L,10,0) -> Kinh | M38: Kinh | N38: =VLOOKUP($B38,Sheet3!$B:$I,7,0) -> #N/A | O38: =VLOOKUP($B38,Sheet4!$B:$L,11,0) -> 1430 | P38: Không | Q38: S24-63QT-KDQT | R38: Quản trị kinh doanh quốc tế | S38: K63 | T38: Chính quy | U38: 2.32 | V38: Hoạt động tuyển dụng tại công ty TNHH Tư vấn và Đầu Tư Vietland | W38: TS. Trần Thị Thanh Huyền | Y38: Bộ môn Kế toán và Quản trị kinh doanh
A39: 36 | B39: 2154077824 | C39: Trần Nguyễn Thông | D39: =VLOOKUP(B39,Sheet3!$B:$I,3,0) -> #N/A | E39: =VLOOKUP($B39,Sheet4!$B:$L,4,0) -> 13/10/2003 | F39: 13/10/2003 | G39: =VLOOKUP($B39,Sheet3!$B:$I,5,0) -> #N/A | H39: =VLOOKUP($B39,Sheet4!$B:$L,5,0) -> Hóc môn, Tp.HCM | I39: =VLOOKUP(B39,[1]Sheet3!$D:$K,5,0) -> TPHCM | J39: Thành phố Hồ Chí Minh | K39: =VLOOKUP($B39,Sheet3!$B:$I,6,0) -> #N/A | L39: =VLOOKUP($B39,Sheet4!$B:$L,10,0) -> Kinh | M39: Kinh | N39: =VLOOKUP($B39,Sheet3!$B:$I,7,0) -> #N/A | O39: =VLOOKUP($B39,Sheet4!$B:$L,11,0) -> 325 | P39: Không | Q39: S24-63LG1 | R39: Logistics và quản lý chuỗi cung ứng | S39: K63 | T39: Chính quy | U39: 2.37 | V39: Thúc đẩy hoạt động bán hàng tại Công ty TNHH TMDV Việt Nhất Nghệ | W39: TS. Trần Văn Biên | X39: ThS. Phạm Thị Duấn | Y39: Bộ môn Kế toán và Quản trị kinh doanh
A40: 37 | B40: 2154077878 | C40: Nguyễn Văn Linh | D40: =VLOOKUP(B40,Sheet3!$B:$I,3,0) -> #N/A | E40: =VLOOKUP($B40,Sheet4!$B:$L,4,0) -> 29/10/2003 | F40: 29/10/2003 | G40: =VLOOKUP($B40,Sheet3!$B:$I,5,0) -> #N/A | H40: =VLOOKUP($B40,Sheet4!$B:$L,5,0) -> Bình Định | I40: =VLOOKUP(B40,[1]Sheet3!$D:$K,5,0) -> Xã Mỹ Quang, huyện Phù Mỹ, tỉnh Bình Định | J40: Gia Lai | K40: =VLOOKUP($B40,Sheet3!$B:$I,6,0) -> #N/A | L40: =VLOOKUP($B40,Sheet4!$B:$L,10,0) -> Kinh | M40: Kinh | N40: =VLOOKUP($B40,Sheet3!$B:$I,7,0) -> #N/A | O40: =VLOOKUP($B40,Sheet4!$B:$L,11,0) -> 379 | P40: Không | Q40: S24-63LG1 | R40: Logistics và quản lý chuỗi cung ứng | S40: K63 | T40: Chính quy | U40: 2.1 | V40: Hoàn thiện quy trình nhập khẩu hàng hóa nguyên container bằng đường biển tại Công ty TNHH MTV Ứng Dụng Công Nghệ Kỹ Thuật Nhựa Âu Lạc | W40: TS. Trần Văn Biên | X40: ThS. Phạm Thị Duấn | Y40: Bộ môn Kế toán và Quản trị kinh doanh
...

Sheet Sheet7
A1: GV Hướng dẫn 1 | B1: Số SV HD | C1: Số SV có GVHD 2 | D1: GV Hướng dẫn 2 | E1: Số SV HD
A2: ThS. Dương Quốc Minh Triều | B2: =COUNTIF(TH!W:W,A2) -> 5 | C2: =COUNTIFS(TH!W4:W300,A2,TH!X4:X300,"<>") -> 0 | D2: ThS. Phạm Thị Duấn | E2: =COUNTIF(TH!X:X,D2) -> 8
A3: ThS. Nguyễn Thị Diễm Trang | B3: =COUNTIF(TH!W:W,A3) -> 5 | C3: =COUNTIFS(TH!W5:W301,A3,TH!X5:X301,"<>") -> 0 | D3: ThS. Lê Văn Tiến Hưng | E3: =COUNTIF(TH!X:X,D3) -> 4
A4: ThS. Đỗ Duy Khương | B4: =COUNTIF(TH!W:W,A4) -> 5 | C4: =COUNTIFS(TH!W6:W302,A4,TH!X6:X302,"<>") -> 0 | D4: TS. Lê Công Chính | E4: =COUNTIF(TH!X:X,D4) -> 4
A5: TS. Hà Kiên Tân | B5: =COUNTIF(TH!W:W,A5) -> 6 | C5: =COUNTIFS(TH!W7:W303,A5,TH!X7:X303,"<>") -> 0 | D5: TS. Lê Thị Hòa Bình | E5: =COUNTIF(TH!X:X,D5) -> 3
A6: TS. Trần Thị Thanh Huyền | B6: =COUNTIF(TH!W:W,A6) -> 7 | C6: =COUNTIFS(TH!W8:W304,A6,TH!X8:X304,"<>") -> 0 | D6: TS. Đặng Đồng Nguyên | E6: =COUNTIF(TH!X:X,D6) -> 4
A7: ThS. Tăng Thị Lưu | B7: =COUNTIF(TH!W:W,A7) -> 7 | C7: =COUNTIFS(TH!W9:W305,A7,TH!X9:X305,"<>") -> 0 | D7: ThS. Phạm Anh Tuấn | E7: =COUNTIF(TH!X:X,D7) -> 2
A8: TS. Trần Văn Biên | B8: =COUNTIF(TH!W:W,A8) -> 8 | C8: =COUNTIFS(TH!W10:W306,A8,TH!X10:X306,"<>") -> 8 | D8: TS. Đặng Văn Phú | E8: =COUNTIF(TH!X:X,D8) -> 14
A9: ThS. Trần Đức Thành | B9: =COUNTIF(TH!W:W,A9) -> 4 | C9: =COUNTIFS(TH!W11:W307,A9,TH!X11:X307,"<>") -> 0 | D9: TS. Phan Khanh Khánh | E9: =COUNTIF(TH!X:X,D9) -> 2
A10: ThS. Nguyễn Thị Hồng Hạnh | B10: =COUNTIF(TH!W:W,A10) -> 5 | C10: =COUNTIFS(TH!W12:W308,A10,TH!X12:X308,"<>") -> 0 | E10: =SUM(E2:E9) -> 41
A11: ThS. Lữ Thị Thanh Thúy | B11: =COUNTIF(TH!W:W,A11) -> 7 | C11: =COUNTIFS(TH!W13:W309,A11,TH!X13:X309,"<>") -> 0
A12: ThS. Đỗ Thị Thu Thủy | B12: =COUNTIF(TH!W:W,A12) -> 8 | C12: =COUNTIFS(TH!W14:W310,A12,TH!X14:X310,"<>") -> 0
A13: ThS. Nguyễn Thị Diện | B13: =COUNTIF(TH!W:W,A13) -> 6 | C13: =COUNTIFS(TH!W15:W311,A13,TH!X15:X311,"<>") -> 0
A14: ThS. Phan Thị Tài | B14: =COUNTIF(TH!W:W,A14) -> 3 | C14: =COUNTIFS(TH!W16:W312,A14,TH!X16:X312,"<>") -> 0
A15: ThS. Trần Ngọc Dân | B15: =COUNTIF(TH!W:W,A15) -> 3 | C15: =COUNTIFS(TH!W17:W313,A15,TH!X17:X313,"<>") -> 0
A16: TS. Hoàng Văn Quý | B16: =COUNTIF(TH!W:W,A16) -> 4 | C16: =COUNTIFS(TH!W18:W314,A16,TH!X18:X314,"<>") -> 0
A17: ThS. Nguyễn Thị Hồng Tú | B17: =COUNTIF(TH!W:W,A17) -> 3 | C17: =COUNTIFS(TH!W19:W315,A17,TH!X19:X315,"<>") -> 0
A18: ThS. Nguyễn Thị Kim Phụng | B18: =COUNTIF(TH!W:W,A18) -> 3 | C18: =COUNTIFS(TH!W20:W316,A18,TH!X20:X316,"<>") -> 0
A19: TS. Hoàng Thị Kiều Anh | B19: =COUNTIF(TH!W:W,A19) -> 5 | C19: =COUNTIFS(TH!W21:W317,A19,TH!X21:X317,"<>") -> 0
A20: ThS. Nguyễn Anh Tú | B20: =COUNTIF(TH!W:W,A20) -> 3 | C20: =COUNTIFS(TH!W22:W318,A20,TH!X22:X318,"<>") -> 0
A21: ThS. Vũ Thị Hạnh | B21: =COUNTIF(TH!W:W,A21) -> 2 | C21: =COUNTIFS(TH!W23:W319,A21,TH!X23:X319,"<>") -> 0
A22: PGS.TS. Trần Đăng An | B22: =COUNTIF(TH!W:W,A22) -> 8 | C22: =COUNTIFS(TH!W24:W320,A22,TH!X24:X320,"<>") -> 4
... A35: TS. Nguyễn Thị Phương Mai | B35: =COUNTIF(TH!W:W,A35) -> 10 | C35: =COUNTIFS(TH!W37:W333,A35,TH!X37:X333,"<>") -> 0
B36: =SUM(B2:B35) -> 198 | C36: =SUM(C2:C35) -> 41

Sheet Sheet1
A1: STT | B1: Họ và tên | C1: MSSV | D1: Lớp | E1: Số điểm tích lũy | F1: Ngành | G1: Điều kiện nhận HPTN | H1: Ghi Chú
A2: 1 | B2: Cáp Đức Hiệp | C2: 1851012851 | D2: S21-60C | E2: 2.03 | F2: Kỹ thuật xây dựng công trình thủy | G2: Đủ đk
A3: 2 | B3: Nguyễn Phước Việt | C3: 1851013270 | D3: S21-60C | E3: 1.96 | F3: Kỹ thuật xây dựng công trình thủy | G3: Đủ đk
A4: 3 | B4: Nguyễn Cao Lương | C4: 1851043176 | D4: S21-60CX2 | E4: 2.01 | F4: Kỹ thuật xây dựng | G4: Đủ đk
A5: 4 | B5: Phạm Hoàng Ngọc Long | C5: 1851042736 | D5: S21-60CX2 | E5: 1.96 | F5: Kỹ thuật xây dựng | G5: Đủ đk
A6: 5 | B6: Trần Kim Thiên | C6: 1851133239 | D6: S21-60GT | E6: 1.95 | F6: Kỹ thuật xây dựng công trình giao thông | G6: Đủ đk
A7: 6 | B7: Trần Văn Bảo | C7: 1851132863 | D7: S21-60GT | E7: 2 | F7: Kỹ thuật xây dựng công trình giao thông | G7: Đủ đk
A8: 7 | B8: Dương Hải Duy | C8: 1851022689 | D8: S21-60N | E8: 1.99 | F8: Kỹ thuật tài nguyên nước | G8: Đủ đk
A9: 8 | B9: Lưu Thị Linh Uyên | C9: 1951015717 | D9: S22-61C | E9: 1.97 | F9: Kỹ thuật xây dựng công trình thủy | G9: Đủ đk
A10: 9 | B10: Nguyễn Thị Tố Quyên | C10: 1951015150 | D10: S22-61C | E10: 2 | F10: Kỹ thuật xây dựng công trình thủy | G10: Đủ đk
A11: 10 | B11: Đặng Đình Tài | C11: 1951015231 | D11: S22-61C | E11: 2.01 | F11: Kỹ thuật xây dựng công trình thủy | G11: Đủ đk
A12: 11 | B12: Phạm Quốc Huy | C12: 1951015560 | D12: S22-61C | E12: 1.96 | F12: Kỹ thuật xây dựng công trình thủy | G12: Đủ Đk
A13: 12 | B13: Nguyễn Hoàng Hữu Tài | C13: 1951045651 | D13: S22-61CX | E13: 2.2 | F13: Kỹ thuật xây dựng | G13: Đủ đk
A14: 13 | B14: Phan Lê Anh Kiệt | C14: 1951045142 | D14: S22-61CX | E14: 1.98 | F14: Kỹ thuật xây dựng | G14: Đủ đk
A15: 14 | B15: Nguyễn Thế Anh | C15: 1951040205 | D15: S22-61CX | E15: 2.23 | F15: Kỹ thuật xây dựng | G15: Đủ đk
A16: 15 | B16: Bùi Ngọc Nhậm | C16: 1951045587 | D16: S22-61CX | E16: 2.01 | F16: Kỹ thuật xây dựng | G16: Đủ Đk
A17: 16 | B17: Phạm Đàm Mỹ Duyên | C17: 1954025556 | D17: S22-61QT-Mar | E17: 1.91 | F17: Quản trị Marketing | G17: Đủ đk
A18: 17 | B18: Nguyễn Thị Ngọc Huyền | C18: 1954025484 | D18: S22-61QT-TMĐT | E18: 2.11 | F18: Quản trị kinh doanh thương mại điện tử | G18: Đủ đk
A19: 18 | B19: Đỗ Ngọc Quỳnh Anh | C19: 1954025583 | D19: S22-61QT-TMĐT | E19: 1.93 | F19: Quản trị kinh doanh thương mại điện tử | G19: Đủ đk
A20: 19 | B20: Võ Huy Hoà | C20: 2051017011 | D20: S23-62C | E20: 2.02 | F20: Kỹ thuật xây dựng công trình thủy | G20: Đủ đk
... A23: 22 | B23: Nguyễn Khánh An | C23: 2051017000 | D23: S23-62C | E23: 2.1 | F23: Kỹ thuật xây dựng công trình thủy | G23: Đủ đk
A24: 23 | B24: Phạm Hải Đăng | C24: 2051117603 | D24: S23-62CT | E24: 2.08 | F24: Công nghệ kỹ thuật xây dựng | G24: Đủ đk
A25: 24 | B25: Lương Nguyễn Đăng Khiêm | C25: 2051077592 | D25: S23-62CTN | E25: 2.13 | F25: Kỹ thuật cấp thoát nước | G25: Đủ đk
A26: 25 | B26: Nguyễn Tùng Lâm | C26: 2051047095 | D26: S23-62CX | E26: 1.96 | F26: Kỹ thuật xây dựng | G26: Đủ đk
A27: 26 | B27: Trương Quốc Thịnh | C27: 2051047478 | D27: S23-62CX | E27: 1.96 | F27: Kỹ thuật xây dựng | G27: Đủ đk
A28: 27 | B28: Trần Văn Huy | C28: 2051047092 | D28: S23-62CX | E28: 2.06 | F28: Kỹ thuật xây dựng | G28: Đủ đk
A29: 28 | B29: Mai Phong Phú | C29: 2051047109 | D29: S23-62CX | E29: 1.99 | F29: Kỹ thuật xây dựng | G29: Đủ đk
A30: 29 | B30: Nguyễn Đăng Khoa | C30: 2051047481 | D30: S23-62CX | E30: 2.83 | F30: Kỹ thuật xây dựng | G30: Đủ đk
A31: 30 | B31: Nguyễn Thị Bích Ngân | C31: 2054037737 | D31: S23-62KT | E31: 2.47 | F31: Kế toán | G31: Đủ Đk
A32: 31 | B32: Nguyễn Đại Thuý An | C32: 2051027046 | D32: S23-62N | E32: 2.14 | F32: Kỹ thuật tài nguyên nước | G32: Đủ đk
A33: 32 | B33: Rmah Yen | C33: 2051027473 | D33: S23-62N | E33: 2.02 | F33: Kỹ thuật tài nguyên nước | G33: Đủ đk
A34: 33 | B34: Nguyễn Đào Như Bình | C34: 2051027048 | D34: S23-62N | E34: 2.01 | F34: Kỹ thuật tài nguyên nước | G34: Đủ đk
A35: 34 | B35: Trần Thị Hải Yến | C35: 2054027653 | D35: S23-62QT-MAR | E35: 2.11 | F35: Quản trị Marketing | G35: Đủ Đk
A36: 35 | B36: Đặng Cao Thiên Phước | C36: 2051067538 | D36: S23-62TH | E36: 2.18 | F36: Công nghệ thông tin | G36: Đủ đk
A37: 36 | B37: Trần Huy Hoàng | C37: 2051067521 | D37: S23-62TH | E37: 2.58 | F37: Công nghệ thông tin | G37: Đủ đk
A38: 37 | B38: Vũ Trí Minh | C38: 2051067806 | D38: S23-62TH | E38: 2.26 | F38: Công nghệ thông tin | G38: Đủ Đk
A39: 38 | B39: Nguyễn Anh Hào | C39: 2051067773 | D39: S23-62TH | E39: 1.94 | F39: Công nghệ thông tin | G39: Đủ Đk
A40: 39 | B40: Đỗ Quốc Thái | C40: 2051067231 | D40: S23-62TH | E40: 1.94 | F40: Công nghệ thông tin | G40: Đủ Đk
A41: 40 | B41: Trần Lê Thanh Vy | C41: 2054027441 | D41: S24-62QT-KDQT | E41: 1.79 | F41: Quản trị kinh doanh quốc tế | G41: Đủ đk
A42: 41 | B42: Nguyễn Ngọc Xuân Trang | C42: 2054027428 | D42: S24-62QT-Mar | E42: 2.24 | F42: Quản trị Marketing | G42: Đủ đk
...

Sheet Sheet2
A1: STT | B1: Mã sinh viên | C1: Họ tên | D1: Lớp | E1: Tên đề tài | F1: Tên đề tài hiệu chỉnh | G1: Giảng viên hướng dẫn 1 | H1: Hiệu chỉnh giảng viên hướng dẫn | I1: Giảng viên hướng dẫn 2 | J1: Bộ môn
A2: 1 | B2: 1954025484 | C2: Nguyễn Thị Ngọc Huyền | D2: S22-61QT-TMĐT | E2: Hoàn thiện hoạt động bán hàng tại Công ty Cổ phần Dịch vụ Xây dựng Địa ốc An Trường Thịnh | F2: Hoàn thiện hoạt động bán hàng tại Công ty Cổ phần Đầu tư và Phát triển Bất động sản Richard Land | G2: ThS. Dương Quốc Minh Triều | J2: Bộ môn Kế toàn và Quản trị kinh doanh
A3: 2 | B3: 1954025583 | C3: Đỗ Ngọc Quỳnh Anh | D3: S22-61QT-TMĐT | E3: Hoàn thiện công tác đào tạo nguồn nhân lực tại Công ty Cổ Phần Trải Nghiệm Toàn Cầu | F3: Hoàn thiện công tác đào tạo nguồn nhân lực tại Công ty Trách Nhiệm Hữu Hạn Merimen Technologies (VIỆT NAM) | G3: ThS. Dương Quốc Minh Triều | J3: Bộ môn Kế toàn và Quản trị kinh doanh
A4: 3 | B4: 2054027428 | C4: Nguyễn Ngọc Xuân Trang | D4: S24-62QT-Mar | E4: Thực trạng hoạt động marketing và marketing mix cho sản phẩm “TOEIC 4 kỹ năng” của Công ty TNHH Tư vấn và Giáo dục Thiên Bảo | F4: Thực trạng hoạt động marketing mix tại Công ty TNHH Tư vấn và Giáo dục Thiên Bảo | G4: TS. Trần Thị Thanh Huyền | J4: Bộ môn Kế toàn và Quản trị kinh doanh
A5: 4 | B5: 2154037772 | C5: Bùi Thị Thu Nga | D5: S24-63KT | E5: Kế toán thanh toán với người bán, người mua tại Ngân Hàng Thương Mại Cổ Phần Quốc Tế Việt Nam | F5: Kế toán thanh toán với người mua người bán tại Công ty cổ phần Homedoor Vina. | G5: ThS. Nguyễn Thị Diện | J5: Bộ môn Kế toàn và Quản trị kinh doanh
A6: 5 | B6: 2154027124 | C6: Nguyễn Thị Xuân Quỳnh | D6: S24-63KT | E6: Kế toán tài sản cố định tại Công ty Đấu Giá Hợp Danh Đông Nam | F6: Kế toán thanh toán với người mua, người bán tại Công Ty Cổ Phần Tập Đoàn UNIS | G6: ThS. Nguyễn Thị Diện | J6: Bộ môn Kế toàn và Quản trị kinh doanh
A7: 6 | B7: 2154077387 | C7: Nguyễn Thị Thanh Ngân | D7: S24-63LG2 | E7: Hoàn thiện hoạt động giao nhận hàng hóa nhập khẩu nguyên container bằng đường biển tại Công ty TNHH TMDV Vạn Hải | F7: Hoàn thiện hoạt động giao nhận hàng hóa nhập khẩu nguyên container bằng đường biển tại Công ty TNHH TM VÀ DV VẠN HẢI | G7: TS. Trần Văn Biên | I7: ThS. Phạm Thị Duấn | J7: Bộ môn Kế toàn và Quản trị kinh doanh
A8: 7 | B8: 2154027661 | C8: Bùi Thị Phương Dung | D8: S24-63QT-KDQT | E8: Hoạt động tuyển dụng tại Công ty TNHH Đầu tư Vận tải Bảo Anh: Thực trạng và giải pháp | F8: Hoạt động tuyển dụng tại Công ty TNHH Một Thành Viên TMDV Quốc Dũng: Thực trạng và giải pháp | G8: TS. Trần Thị Thanh Huyền | J8: Bộ môn Kế toàn và Quản trị kinh doanh
A9: 8 | B9: 2154025165 | C9: Nguyễn Khánh Vân | D9: S24-63QT-KDQT | E9: Hoạt động tuyển dụng tại công ty TNHH Thương Mại Và Đầu Tư SRT Miền Nam: Thực trạng và giải pháp | F9: Hoàn thiện công tác chăm sóc khách hàng tại Radisson Blu Resort Phú Quốc | G9: TS. Trần Thị Thanh Huyền | J9: Bộ môn Kế toàn và Quản trị kinh doanh
A10: 9 | B10: 2154027096 | C10: Phạm Thị Thuý Hiền | D10: S24-63QT-Mar | E10: Hoàn thiện công tác chăm sóc khách hàng tại Công ty TNHH Vận Tải Dương Nguyên ạ | F10: Hoàn thiện công tác chăm sóc khách hàng tại Công ty TNHH Vận Tải Dương Nguyên | G10: ThS. Dương Quốc Minh Triều | J10: Bộ môn Kế toàn và Quản trị kinh doanh
A11: 10 | B11: 2154027689 | C11: Đỗ Ngọc Linh | D11: S24-63QT-Mar | E11: Hoàn thiện khung năng lực và chương trình đào tạo cho đội ngũ hoạt náo viên tại Công ty cổ phần Central Retail (Việt Nam) | F11: Hoàn thiện công tác đào tạo nguồn nhân lực tại Công ty Cổ phần Central Retail Corporation (Việt Nam) | G11: TS. Hà Kiên Tân | H11: TS. Trần Thị Thanh Huyền | J11: Bộ môn Kế toàn và Quản trị kinh doanh
A12: 11 | B12: 1851013270 | C12: Nguyễn Phước Việt | D12: S21-60C | E12: Thiết kế hồ chứa Hồ Móng | F12: Thiết kế hồ chứa Hồ Mòng | G12: TS. Phạm Ngọc Thịnh | J12: Bộ môn Kỹ thuật công trình
A13: 12 | B13: 2051117603 | C13: Phạm Hải Đăng | D13: S23-62CT | E13: Thiết kế tổ chức thi công công trình cống Cái Bè Sáu - Bến Tre | F13: Thiết kế tổ chức thi công công trình cống Cái Bè Sâu - Bến Tre | G13: PGS.TS. Lê Trung Thành | I13: TS. Phan Khanh Khánh | J13: Bộ môn Kỹ thuật công trình
A14: 13 | B14: 2051077592 | C14: Lương Nguyễn Đăng Khiêm | D14: S23-62CTN | E14: Thiết kế hệ thống cấp nước Khu đô thị mới An Lạc 1, tỉnh Tiền Giang tới năm 2040 | F14: Thiết kế hệ thống cấp nước Khu đô thị mới An Lạc 1, tỉnh Đồng Tháp tới năm 2040 | G14: PGS.TS. Trần Đăng An | I14: TS. Lê Công Chính | J14: Bộ môn Kỹ thuật tài nguyên nước và môi trường
A15: 14 | B15: 2151017502 | C15: Nguyễn Diệp Quốc Giảng | D15: S24-63CTN | E15: Thiết kế hệ thống cấp nước đô thị Tân Châu, tỉnh Tiền Giang tới năm 2040 | F15: Thiết kế hệ thống cấp nước đô thị Tân Châu, tỉnh Đồng Tháp tới năm 2040 | G15: PGS.TS. Trần Đăng An | J15: Bộ môn Kỹ thuật tài nguyên nước và môi trường
A16: 15 | B16: 2151017525 | C16: Nguyễn Ngọc Trường | D16: S24-63CTN | E16: Thiết kế hệ thống cấp nước Khu đô thị thương mại dịch vụ ven sông phía Đông Sa Đéc, tỉnh Tiền Giang tới năm 2040 | F16: Thiết kế hệ thống cấp nước Khu đô thị thương mại dịch vụ ven sông phía Đông Sa Đéc, tỉnh Đồng Tháp tới năm 2040 | G16: PGS.TS. Trần Đăng An | I16: TS. Lê Công Chính | J16: Bộ môn Kỹ thuật tài nguyên nước và môi trường
A17: 16 | B17: 2151017500 | C17: Nguyễn Chí Công | D17: S24-63CTN | E17: Thiết kế Hệ thống cấp nước phường Phú Lợi và phường Sóc Trăng, Thành phố Cần Thơ tới năm 2040 | F17: Thiết kế hệ thống cấp nước Khu đô thị Long Hòa, Dầu Tiếng, TP. Hồ Chí Minh tới 2040 | G17: PGS.TS. Trần Đăng An | J17: Bộ môn Kỹ thuật tài nguyên nước và môi trường
A18: 17 | B18: 2151017343 | C18: Chung Ngọc Hoài Dung | D18: S24-63N | E18: Quy hoạch hệ thống thuỷ lợi hồ chứa Cam Ranh | F18: Quy hoạch hệ thống thuỷ lợi hồ chứa nước Cam Ranh | G18: TS. Đặng Đồng Nguyên | I18: TS. Lê Thị Hòa Bình | J18: Bộ môn Kỹ thuật tài nguyên nước và môi trường
A19: 18 | B19: 2031070253 | C19: Nguyễn Ngọc Sơn | D19: SG24CTN | E19: Thiết kế hệ thống cấp nước Khu đô dân cư Hòa Thành, tỉnh Tiền Giang tới năm 2040 | F19: Thiết kế hệ thống cấp nước Khu dân cư Hòa Thành, tỉnh Đồng Tháp tới năm 2040 | G19: PGS.TS. Trần Đăng An | I19: TS. Lê Công Chính | J19: Bộ môn Kỹ thuật tài nguyên nước và môi trường

Sheet Sheet3
A1: 261544163 | B1: 2051117885 | C1: Phan Hoàng Vũ | D1: 14/11/1998 | E1: Nam | F1: Bình Thuận | I1: K62
A2: 261660192 | B2: 2054037750 | C2: Trần Lan Anh | D2: 01/03/2002 | E2: Nữ | F2: Bình Thuận | I2: K62
A3: 241903281 | B3: 2051077751 | C3: Cao Minh Hoàng | D3: 24/12/2002 | E3: Nam | F3: Đắk Lắk | I3: K62
A4: 301687967 | B4: 2054037752 | C4: Trần Thị Yến Huỳnh | D4: 23/02/2000 | E4: Nữ | F4: Long An | I4: K62
A5: 321793552 | B5: 2054027753 | C5: Phạm Thanh Triều | D5: 13/10/2002 | E5: Nam | F5: Bến Tre | I5: K62
A6: 281294313 | B6: 2051067754 | C6: Nguyễn Nhật Minh | D6: 23/06/2002 | E6: Nam | F6: Bình Dương | I6: K62
A7: 079202005751 | B7: 2051027755 | C7: Phạm Công Danh | D7: 09/10/2002 | E7: Nam | F7: Hồ Chí Minh | I7: K62
A8: 080202000334 | B8: 2054037756 | C8: Hồ Quang Thịnh | D8: 13/10/2002 | E8: Nam | F8: Hồ Chí Minh | I8: K62
A9: 342069050 | B9: 2051077757 | C9: Nguyễn Thị Kim Tỏa | D9: 18/05/2002 | E9: Nữ | F9: Đồng Tháp | I9: K62
A10: 079202036660 | B10: 2051067758 | C10: Võ Vũ Trường Giang | D10: 20/04/2002 | E10: Nam | F10: Hồ Chí Minh | I10: K62
A11: 241997506 | B11: 2051067759 | C11: Trần Văn Phúc | D11: 20/09/2002 | E11: Nam | F11: Đắk Lắk | I11: K62
A12: 077302001384 | B12: 2054027760 | C12: Bùi Thị Tuyết Nhi | D12: 10/10/2002 | E12: Nữ | F12: Bà Rịa - Vũng Tàu | I12: K62
A13: 000215569483 | B13: 2051047761 | C13: Nguyễn Tiến Nam | D13: 13/11/2002 | E13: Nam | F13: Bình Định | I13: K62
A14: 241759985 | B14: 2051067762 | C14: Nguyễn Đình Phúc | D14: 12/09/2001 | E14: Nam | F14: Đắk Lắk | I14: K62
A15: 036302009733 | B15: 2054037763 | C15: Trần Thu Phương | D15: 09/03/2002 | E15: Nữ | F15: Quảng Bình | I15: K62
... A134: 215558856 | B134: 2054037883 | C134: Nguyễn Thị Kiêm | D134: 10/09/2002 | E134: Nữ | F134: Bình Định | I134: K62
A135: 001202008785 | B135: 2051017463 | C135: Nguyễn Khánh An | D135: 29/09/2002 | E135: Nam | I135: K62
A136: 034202000402 | B136: 2051017003 | C136: Trương Việt Anh | D136: 15/05/2002 | E136: Nam | I136: K62
A137: 312468513 | B137: 2051017006 | C137: Lê Tấn Đạt | D137: 30/11/2001 | E137: Nam | I137: K62
A138: 261568058 | B138: 2051017007 | C138: Đặng Nguyễn Hồ Điệp | D138: 08/01/2002 | E138: Nam | I138: K62
A139: 231369966 | B139: 2051017462 | C139: Lê Công Đức | D139: 17/09/2002 | E139: Nam | I139: K62
A140: 184454699 | B140: 2051017011 | C140: Võ Huy Hòa | D140: 19/02/2002 | E140: Nam | I140: K62
A141: 276064702 | B141: 2051017460 | C141: Nguyễn Phú Hùng | D141: 08/11/2002 | E141: Nam | I141: K62
A142: 382003324 | B142: 2051017015 | C142: Đặng Thanh Khiết | D142: 07/11/2002 | E142: Nam | I142: K62
A143: 261617865 | B143: 2051017019 | C143: Trần Khánh Ly | D143: 25/02/2002 | E143: Nữ | I143: K62
A144: 241779452 | B144: 2051017021 | C144: Bùi Thị Bích Ngọc | D144: 18/12/2001 | E144: Nữ | I144: K62
A145: 312490737 | B145: 2051017023 | C145: Nguyễn Quốc Trọng Nhân | D145: 25/07/2002 | E145: Nam | I145: K62
A146: 381972288 | B146: 2051017024 | C146: Biện Minh Nhựt | D146: 11/02/2002 | E146: Nam | I146: K62
... A424: 082302000094 | B424: 2054037743 | C424: Ngô Võ Hoàng Thơ | D424: 14/02/2002 | E424: Nữ | I424: K62
A425: 042203002587 | B425: 2251018004 | C425: Trần Đức Công | D425: 14/08/2003 | E425: Nam | G425: Kinh | H425: Công giáo | I425: K64
A426: 044204000428 | B426: 2251018005 | C426: Trần Mạnh Cường | D426: 03/02/2004 | E426: Nam | G426: Kinh | H426: Không | I426: K64
A427: 034204005995 | B427: 2251018011 | C427: Lê Anh Đức | D427: 12/12/2004 | E427: Nam | G427: Kinh | H427: Không | I427: K64
A428: 072204000735 | B428: 2251018008 | C428: Võ Khánh Duy | D428: 19/03/2004 | E428: Nam | G428: Kinh | H428: Phật giáo | I428: K64
A429: 082304002960 | B429: 2251018013 | C429: Nguyễn Thị Ngọc Hân | D429: 13/09/2004 | E429: Nữ | G429: Kinh | H429: Không | I429: K64
A430: 077204003082 | B430: 2251018018 | C430: Lương Bảo Huy | D430: 08/10/2004 | E430: Nam | G430: Kinh | H430: Không | I430: K64
A431: 060204006975 | B431: 2251018021 | C431: Võ Đan Huy | D431: 11/01/2004 | E431: Nam | G431: Kinh | H431: Không | I431: K64
A432: 060204002876 | B432: 2251018026 | C432: Đỗ Phạm Duy Khang | D432: 07/08/2004 | E432: Nam | G432: Kinh | H432: Không | I432: K64
A433: 083304007378 | B433: 2251018028 | C433: Lê Trần Kim Khánh | D433: 12/08/2004 | E433: Nữ | G433: Kinh | H433: Không | I433: K64
A434: 096204008943 | B434: 2251018029 | C434: Trần Quốc Khánh | D434: 17/12/2004 | E434: Nam | G434: Kinh | H434: Không | I434: K64
A435: 301891763 | B435: 2251018030 | C435: Huỳnh Hữu Khoa | D435: 16/11/2004 | E435: Nam | G435: Kinh | H435: Không | I435: K64
...

Sheet Sheet4
A1: DANH SÁCH SINH VIÊN - Phân hiệu Miền Nam - K63
A2: STT | B2: Mã sinh viên | C2: Tên sinh viên | D2: Giới tính | E2: Ngày sinh | F2: Nơi sinh | G2: CMND | H2: Ngày cấp | I2: Nơi cấp | J2: Số điện thoại | K2: Dân tộc | L2: Tôn giáo | M2: Địa chỉ liên hệ | N2: Họ tên bố | O2: Số điện thoại bố | P2: Họ tên mẹ | Q2: Số điện thoại mẹ | R2: Lớp | S2: Ngành | T2: Khoa | U2: Khóa | V2: Quyết định | W2: Trạng thái
A3: 1 | B3: 2151017000 | C3: Nguyễn Duy Anh | D3: Nam | E3: 04/09/2003 | F3: Tỉnh Hòa Bình | G3: 113818325 | J3: 0915915398 | K3: Kinh | L3: 1167 | M3: Số nhà 2, Ngõ 97, Đường Phan Huy Chú, Tổ 4, Phường Đồng Tiến, Thành phố Hòa Bình, Tỉnh Hòa Bình | R3: S24-63C | S3: Kỹ thuật xây dựng công trình thủy | T3: Khoa Công trình | U3: K63
A4: 2 | B4: 2151067373 | C4: Lê Duy Anh | D4: Nam | E4: 13/09/2003 | F4: Bến Tre | G4: 083203001623 | J4: 0372497405 | K4: Kinh | L4: 35 | M4: Xã An Định , Huyện Mỏ Cày Nam , Tỉnh Bến Tre | N4: Lê Văn Trung | P4: Nguyễn Thị Ngọc Tuyết | R4: S24-63C | S4: Kỹ thuật xây dựng công trình thủy | T4: Khoa Công trình | U4: K63
A5: 3 | B5: 2151017351 | C5: Phan Thanh Bình | D5: Nam | E5: 27/12/2003 | F5: Cà Mau | G5: 096203009313 | J5: 0836885707 | K5: Kinh | L5: 13 | M5: Lý văn lâm khóm 1- phường 1 TP Cà Mau | R5: S24-63C | S5: Kỹ thuật xây dựng công trình thủy | T5: Khoa Công trình | U5: K63
A6: 4 | B6: 2151017001 | C6: Nguyễn Minh Đăng | D6: Nam | E6: 19/10/2003 | F6: Tp.HCM | G6: 079203013902 | J6: 0339314471 | K6: Kinh | L6: Công giáo | M6: 86/7 Trịnh Đình Trọng, Phường Phú Trung, Quận Tân Phú, Thành phố Hồ Chí Minh | R6: S24-63C | S6: Kỹ thuật xây dựng công trình thủy | T6: Khoa Công trình | U6: K63 | V6: Quyết định tam ngừng học - Ngày 04/10/2023; Quyết định quay trở lại trường - Ngày 27/08/2024; | W6: Quay trở lại
A7: 5 | B7: 2151017208 | C7: Lê Phát Đạt | D7: Nam | E7: 28/12/2003 | F7: Kiên Giang | G7: 372040647 | J7: 0347376878 | K7: Kinh | L7: 1375 | M7: tổ 5, khu phố Sư Nam, thị trấn Hòn Đất, huyện Hòn Đất, tỉnh Kiên Giang | N7: Lê Ngọc Tuyên | P7: Nguyễn Thùy Trang | R7: S24-63C | S7: Kỹ thuật xây dựng công trình thủy | T7: Khoa Công trình | U7: K63
A8: 6 | B8: 2151017209 | C8: Phạm Anh Đức | D8: Nam | E8: 11/05/2003 | F8: Đồng Nai | G8: 272945950 | J8: 0932142518 | K8: Kinh | L8: 1376 | M8: Viện thủy lợi môi trường, Số 2 Trường Sa, Phường 17, Quận Bình Thạnh, Thành phố Hồ Chí Minh | N8: Phạm Anh Tuấn | P8: Trịnh Bích Thuận | R8: S24-63C | S8: Kỹ thuật xây dựng công trình thủy | T8: Khoa Công trình | U8: K63
A9: 7 | B9: 2151017003 | C9: Cù Minh Đức | D9: Nam | E9: 08/02/2003 | F9: Bình Định | G9: 215569635 | J9: 0397998028 | K9: Kinh | L9: 1170 | M9: Thôn Lai Nghi, xã Bình Nghi, huyện Tây Sơn, tỉnh Bình Định | N9: Cù Trọng Nhặn | P9: Trần Thị Điểu | R9: S24-63C | S9: Kỹ thuật xây dựng công trình thủy | T9: Khoa Công trình | U9: K63
A10: 8 | B10: 2151017004 | C10: Nguyễn Duy | D10: Nam | E10: 30/11/2003 | F10: Bình Thuận | G10: 261657847 | J10: 0913931240 | K10: Kinh | L10: 1171 | M10: 23 Huỳnh Thị Khá, Phú Thủy, Phan Thiết, Bình Thuận | N10: Nguyễn Văn Dũng | P10: Trần Thị Xuân Lan | R10: S24-63C | S10: Kỹ thuật xây dựng công trình thủy | T10: Khoa Công trình | U10: K63
A11: 9 | B11: 2151017005 | C11: Võ Kế Duy | D11: Nam | E11: 30/05/2003 | F11: Bình Định | G11: 215589333 | J11: 0333861711 | K11: Kinh | L11: 1172 | M11: Xóm 1, Phú An, Tây Xuân, Tây Sơn, Bình Định | N11: Võ Kế Vinh | P11: Đặng Thị Dung | R11: S24-63C | S11: Kỹ thuật xây dựng công trình thủy | T11: Khoa Công trình | U11: K63
A12: 10 | B12: 2151017006 | C12: Phạm Thị Thùy Duyên | D12: Nữ | E12: 01/06/2003 | F12: Đăk Lăk | G12: 241978899 | J12: 0944526775 | K12: Kinh | L12: 1173 | M12: 109B/25 Mai Hắc Đế, tổ 6, khối 2, phường Tân Thành, thành phố Buôn Ma Thuột, tỉnh Đăk Lăk | N12: Phạm Đức Triển | P12: Trần Thị Ngoan | R12: S24-63C | S12: Kỹ thuật xây dựng công trình thủy | T12: Khoa Công trình | U12: K63
A13: 11 | B13: 2151017007 | C13: Nguyễn Trung Hiếu | D13: Nam | E13: 04/06/2003 | F13: Bến Tre | G13: 321797749 | J13: 0365319901 | K13: Kinh | L13: 1174 | M13: Ấp Quí Đức A, xã Qưới Điền, huyện Thạnh Phú, Tỉnh Bến Tre | N13: Nguyễn văn Út | P13: Nguyễn Thị Trang | R13: S24-63C | S13: Kỹ thuật xây dựng công trình thủy | T13: Khoa Công trình | U13: K63
A14: 12 | B14: 2151017008 | C14: Trần Minh Hiếu | D14: Nam | E14: 30/07/2003 | F14: TP.Huế | G14: 215575879 | J14: 0962361761 | K14: Kinh | L14: 1175 | M14: 11 Nguyễn Trung Trực , Phường Nguyễn Văn Cừ , Thành phố Quy Nhơn , Tỉnh Bình Định | N14: Trần Văn Thủy | P14: Lê Thị Dương | R14: S24-63C | S14: Kỹ thuật xây dựng công trình thủy | T14: Khoa Công trình | U14: K63
A15: 13 | B15: 2151017009 | C15: Phan Châu Hoàng | D15: Nam | E15: 10/03/2003 | F15: Bình Định | G15: 052203002533 | H15: 44317 | J15: 0964760729 | K15: Kinh | L15: 1176 | M15: 44 Lê Hồng Phong, Thị trấn Tăng Bạt Hổ, Huyện Hoài Ân, Tỉnh Bình Định | N15: Phan Đình Dũng | P15: Trần Thị Sương | R15: S24-63C | S15: Kỹ thuật xây dựng công trình thủy | T15: Khoa Công trình | U15: K63 | V15: Quyết định quay trở lại trường - Ngày 29/08/2024; Quyết định tam ngừng học - Ngày 23/10/2024; Quyết định tam ngừng học - Ngày 27/12/2023; Quyết định quay trở lại trường - Ngày 20/01/2025; | W15: Quay trở lại
A16: 14 | B16: 2151017010 | C16: Nguyễn Bùi Viết Hưng | D16: Nam | E16: 18/09/2003 | F16: Tây Ninh | G16: 072203003524 | J16: 0383478443 | K16: Kinh | L16: 1177 | M16: Tổ 2, Ấp Bảo, Xã Long Giang, Huyện Bến Cầu, Tỉnh Tây Ninh | N16: Nguyễn Minh Phụng | P16: Bùi Ngọc Châu | R16: S24-63C | S16: Kỹ thuật xây dựng công trình thủy | T16: Khoa Công trình | U16: K63
A17: 15 | B17: 2151017011 | C17: Nguyễn Đào Tuấn Hưng | D17: Nam | E17: 16/03/2003 | F17: Lâm Đồng | G17: 068203001079 | J17: 0971048051 | K17: Kinh | L17: 1178 | M17: Tổ Dân Phố 12, Thị Trấn Cát Tiên, Tỉnh Lâm Đồng | N17: Nguyễn Thanh Sơn | P17: Đào Thị Vân Anh | R17: S24-63C | S17: Kỹ thuật xây dựng công trình thủy | T17: Khoa Công trình | U17: K63 | V17: Quyết định quay trở lại trường - Ngày 30/08/2024; Quyết định tam ngừng học - Ngày 27/12/2023; | W17: Quay trở lại
A18: 16 | B18: 2151017012 | C18: Uông Phạm Nhật Hưng | D18: Nam | E18: 25/08/2003 | F18: Đăk Lăk | G18: 066203015598 | H18: 44445 | J18: 0961812979 | K18: Kinh | L18: 1179 | M18: 17 Thôn Xí Nghiệp Xã Đăk Liêng Huyện Lăk Tỉnh Đăk Lăk | N18: Uông Sỹ Đức | P18: Phạm Thị Hòa | R18: S24-63C | S18: Kỹ thuật xây dựng công trình thủy | T18: Khoa Công trình | U18: K63
A19: 17 | B19: 2151017340 | C19: Phan Nhật Huy | D19: Nam | E19: 16/03/1999 | F19: Phú Yên | G19: 221482022 | J19: 0797929072 | K19: Kinh | L19: 2 | M19: Hòa Mỹ Đông huyện Tây Hòa tỉnh Phú Yên | N19: Phan Văn Hòa | P19: Võ Thị Thanh Thúy | R19: S24-63C | S19: Kỹ thuật xây dựng công trình thủy | T19: Khoa Công trình | U19: K63
A20: 18 | B20: 2151017505 | C20: Lâm Hoàng Huy | D20: Nam | E20: 11/04/2003 | F20: Bạc Liêu | G20: 095203002948 | J20: 0911138820 | K20: Kinh | L20: 6 | M20: TRƯỜNG THPT LÊ VĂN ĐẨU | N20: Lâm Quan Hổ | P20: Từ Thị Hồng | R20: S24-63C | S20: Kỹ thuật xây dựng công trình thủy | T20: Khoa Công trình | U20: K63
A21: 19 | B21: 2154077881 | C21: Đồng Văn Huynh | D21: Nam | E21: 20/01/2003 | F21: Nam Định | G21: 245421130 | J21: 0918997697 | K21: Kinh | L21: 382 | M21: Thôn Đắk Xuân, Xã Nam Xuân, Huyện Krông Nô, Đắk Nông | N21: Đồng Văn Kiền | P21: Nguyễn Thị Hường | R21: S24-63C | S21: Kỹ thuật xây dựng công trình thủy | T21: Khoa Công trình | U21: K63
A22: 20 | B22: 2151017507 | C22: Nguyễn Đình Khôi | D22: Nam | E22: 11/06/2003 | F22: Phan Thiết | G22: 261554829 | J22: 0987744681 | K22: Kinh | L22: 8 | M22: Trường THPT Phan Chu Trinh, 163 Tuyên Quang - Phú Thủy - Phan Thiết - Bình Thuận | N22: Nguyễn Văn Đố | P22: Nguyễn Thị Thùy Linh | R22: S24-63C | S22: Kỹ thuật xây dựng công trình thủy | T22: Khoa Công trình | U22: K63
A23: 21 | B23: 2151017014 | C23: Phạm Trung Kiên | D23: Nam | E23: 25/07/2003 | F23: Ninh Thuận | G23: 264584856 | J23: 0912462261 | K23: Kinh | L23: 1181 | M23: Mỹ Nhơn,Bắc Phong,Thuận Bắc,Ninh Thuận | N23: Phạm Văn An | P23: Hồ Thị Tý | R23: S24-63C | S23: Kỹ thuật xây dựng công trình thủy | T23: Khoa Công trình | U23: K63
A24: 22 | B24: 2151017212 | C24: Nguyễn Trung Kiện | D24: Nam | E24: 06/03/2003 | F24: Cà Mau | G24: 096203001399 | J24: 0981665010 | K24: 1379 | L24: 1379 | M24: Tổ 16, Khóm Thượng 2, thị trấn Thường Thới Tiền, huyện Hồng Ngự, tỉnh Đồng Tháp | N24: Nguyễn Văn MỘng | P24: Đoàn Thị Nhung | R24: S24-63C | S24: Kỹ thuật xây dựng công trình thủy | T24: Khoa Công trình | U24: K63
A25: 23 | B25: 2151017213 | C25: Vũ Nguyễn Ngọc Lâm | D25: Nam | E25: 19/03/2003 | F25: Đồng Nai | G25: 075203022449 | J25: 0785493928 | K25: Kinh | L25: 1380 | M25: 30 đường 10, khu phố 1, phường Bình Trưng Đông, TP. Thủ Đức. | N25: Vũ Ngọc Cường | P25: Nguyễn Thị Huyền Trâm | R25: S24-63C | S25: Kỹ thuật xây dựng công trình thủy | T25: Khoa Công trình | U25: K63
A26: 24 | B26: 2151017508 | C26: Kiều Công Luận | D26: Nam | E26: 18/07/2003 | F26: NInh Thuận | G26: 264582808 | J26: 0369045046 | K26: Chăm | L26: 9 | M26: KIỀU CÔNG LUẬN, Lớp 12A6, Trường THPT An Phước, Phước Dân, Ninh Phước, Ninh Thuận. | N26: Kiều Ngọc | P26: Lưu Thị Khánh Hòa | R26: S24-63C | S26: Kỹ thuật xây dựng công trình thủy | T26: Khoa Công trình | U26: K63
A27: 25 | B27: 2151017509 | C27: Nguyễn Quang Minh | D27: Nam | E27: 14/10/2003 | F27: Tp.HCM | G27: 079203017636 | J27: 0909792431 | K27: Kinh | L27: 10 | M27: 331/45 Tôn Đản, Phường 15, Quận 4 | N27: Nguyễn Tấn Tiếp | P27: Nguyễn Thị Thanh Loan | R27: S24-63C | S27: Kỹ thuật xây dựng công trình thủy | T27: Khoa Công trình | U27: K63
A28: 26 | B28: 2151017018 | C28: Cù Trọng Nghĩa | D28: Nam | E28: 27/04/2003 | F28: Bình Định | G28: 052203000862 | J28: 0377623052 | K28: Kinh | L28: 1185 | M28: Thôn Lai Nghi, xã Bình Nghi, huyện Tây Sơn, tỉnh Bình Định | N28: Cù Trọng Mai | P28: Nguyễn Thị Lệ Thủy | R28: S24-63C | S28: Kỹ thuật xây dựng công trình thủy | T28: Khoa Công trình | U28: K63
A29: 27 | B29: 2151017513 | C29: Nguyễn Thị Yến Nhi | D29: Nữ | E29: 30/05/2003 | F29: Bình Thuận | G29: 261642121 | J29: 0868083416 | K29: Kinh | L29: 14 | M29: Trường THPT Hàm Thuận Bắc, số 437, đường Tám Tháng Tư (8/4), thị trấn Ma Lâm, Hàm Thuận Bắc, Bình Thuận | N29: Nguyễn văn Năm | P29: Lê Thị Hồng | R29: S24-63C | S29: Kỹ thuật xây dựng công trình thủy | T29: Khoa Công trình | U29: K63
A30: 28 | B30: 2151017019 | C30: Võ Thị Tố Như | D30: Nữ | E30: 24/06/2003 | F30: Bà rịa vũng tàu | G30: 077303005355 | J30: 0565730647 | K30: Kinh | L30: 1186 | M30: ấp Tân Hoà, xã Long Tân, Huyện Đất Đỏ, Tỉnh Bà Rịa Vũng Tàu | N30: Võ Hoài Tâm | P30: Nguyễn Thị Ngọc Thúy | R30: S24-63C | S30: Kỹ thuật xây dựng công trình thủy | T30: Khoa Công trình | U30: K63
